Workbook

Sheet Contrato
C2: COMPARATIVO FACUTACION FOTOCOPIADORAS 2022
D4: 44470 | E4: 44501
C5: CONCEPTO | D5: ANTIGUA | E5: ACTUAL | G5: Dif | H5: %
C7: ALQUILER | D7: 563.8 | E7: 390.6 | G7: =D7-E7 -> 173.2 | H7: =+E7/D7-1 -> -0.30720114
B8: COSTO POR COPIA | C8: MODELO WF-5790 - BN | D8: 0.0198 | E8: 0.0198 | G8: =D8-E8 -> 0 | H8: =+E8/D8-1 -> 0
C9: MODELO WF-5790 - COLOR | D9: 0.0504 | E9: 0.0501 | G9: =D9-E9 -> 0.0003 | H9: =+E9/D9-1 -> -0.005952381
C10: MODELO IR-1730i | D10: 0.0111 | E10: 0.0111 | G10: =D10-E10 -> 0 | H10: =+E10/D10-1 -> 0
C11: MODELO MXC-300A - BN | D11: 0.0195 | E11: 0.0193 | G11: =D11-E11 -> 0.0002 | H11: =+E11/D11-1 -> -0.01025641
C12: MODELO MXC-300A - COLOR | D12: 0.0877 | E12: 0.0875 | G12: =D12-E12 -> 0.0002 | H12: =+E12/D12-1 -> -0.0022805017
C13: MODELO WF-5710 BN | D13: 0.0207 | E13: 0.0202 | G13: =D13-E13 -> 0.0005 | H13: =+E13/D13-1 -> -0.024154589
C14: MODELO WF-5710 COLOR | D14: 0.0524 | E14: 0.0519 | G14: =D14-E14 -> 0.0005 | H14: =+E14/D14-1 -> -0.0095419847
C16: Monto en Dolares
C18: CORTE DE 15 A 15 DE CADA MES

Sheet 2021
B2: REPORTE DE COPIAS - REPRODATA 2021-2022
D5: 44409 | H5: 44440 | L5: 44470 | P5: 44501 | T5: 44531
B6: SERIE DE EQUIPO | C6: UBICACION / AREA | D6: Tipo | E6: Cantidad | F6: Precio $ | G6: Total | H6: Tipo | I6: Cantidad | J6: Precio $ | K6: Total | L6: Tipo | M6: Cantidad | N6: Precio $ | O6: Total | P6: Tipo | Q6: Cantidad | R6: Precio $ | S6: Total | T6: Tipo | U6: Cantidad | V6: Precio $ | W6: Total
B7: IR-1730IQFX06246 | C7: Contabilidad | D7: B/N | E7: 2042 | F7: 0.0146 | G7: =+E7*F7 -> 29.8132 | H7: B/N | I7: 1618 | J7: 0.0146 | K7: =+I7*J7 -> 23.6228 | L7: B/N | M7: 2414 | N7: 0.0146 | O7: =+M7*N7 -> 35.2444 | P7: B/N | Q7: 1743 | R7: 0.0111 | S7: =+Q7*R7 -> 19.3473 | T7: B/N | U7: 1642 | V7: 0.0111 | W7: =+U7*V7 -> 18.2262
B8: IR-1730IQFX06246 | C8: Contabilidad | D8: Colores | F8: 0.0545 | G8: =+E8*F8 -> 0 | H8: Colores | J8: 0.0545 | K8: =+I8*J8 -> 0 | L8: Colores | N8: 0.0545 | O8: =+M8*N8 -> 0 | P8: Colores | R8: 0.0501 | S8: =+Q8*R8 -> 0 | T8: Colores | V8: 0.0501 | W8: =+U8*V8 -> 0
B9: X3B7003581 | C9: C&M Oficina | D9: B/N | E9: 279 | F9: 0.0198 | G9: =+E9*F9 -> 5.5242 | H9: B/N | I9: 483 | J9: 0.0198 | K9: =+I9*J9 -> 9.5634 | L9: B/N | M9: 440 | N9: 0.0198 | O9: =+M9*N9 -> 8.712 | P9: B/N | Q9: 306 | R9: 0.0198 | S9: =+Q9*R9 -> 6.0588 | T9: B/N | U9: 579 | V9: 0.0198 | W9: =+U9*V9 -> 11.4642
B10: X3B7003581 | C10: C&M Oficina | D10: Colores | F10: 0.0545 | G10: =+E10*F10 -> 0 | H10: Colores | J10: 0.0545 | K10: =+I10*J10 -> 0 | L10: Colores | M10: 2 | N10: 0.0545 | O10: =+M10*N10 -> 0.109 | P10: Colores | R10: 0.0501 | S10: =+Q10*R10 -> 0 | T10: Colores | V10: 0.0501 | W10: =+U10*V10 -> 0
B11: X3B7003609 | C11: Talento y Cultura | D11: B/N | E11: 965 | F11: 0.0198 | G11: =+E11*F11 -> 19.107 | H11: B/N | I11: 1196 | J11: 0.0198 | K11: =+I11*J11 -> 23.6808 | L11: B/N | M11: 1184 | N11: 0.0198 | O11: =+M11*N11 -> 23.4432 | P11: B/N | Q11: 1186 | R11: 0.0198 | S11: =+Q11*R11 -> 23.4828 | T11: B/N | U11: 3508 | V11: 0.0198 | W11: =+U11*V11 -> 69.4584
B12: X3B7003609 | C12: Talento y Cultura | D12: Colores | E12: 13 | F12: 0.0545 | G12: =+E12*F12 -> 0.7085 | H12: Colores | I12: 437 | J12: 0.0545 | K12: =+I12*J12 -> 23.8165 | L12: Colores | M12: 1556 | N12: 0.0545 | O12: =+M12*N12 -> 84.802 | P12: Colores | Q12: 71 | R12: 0.0501 | S12: =+Q12*R12 -> 3.5571 | T12: Colores | U12: 62 | V12: 0.0501 | W12: =+U12*V12 -> 3.1062
A13: No se usa | B13: X3B7003615 | C13: Disponible | D13: B/N | F13: 0.0198 | G13: =+E13*F13 -> 0 | H13: B/N | I13: 1 | J13: 0.0198 | K13: =+I13*J13 -> 0.0198 | L13: B/N | N13: 0.0198 | O13: =+M13*N13 -> 0 | P13: B/N | R13: 0.0198 | S13: =+Q13*R13 -> 0 | T13: B/N | V13: 0.0198 | W13: =+U13*V13 -> 0
A14: No se usa | B14: X3B7003615 | C14: Disponible | D14: Colores | F14: 0.0545 | G14: =+E14*F14 -> 0 | H14: Colores | I14: 5 | J14: 0.0545 | K14: =+I14*J14 -> 0.2725 | L14: Colores | N14: 0.0545 | O14: =+M14*N14 -> 0 | P14: Colores | R14: 0.0501 | S14: =+Q14*R14 -> 0 | T14: Colores | V14: 0.0501 | W14: =+U14*V14 -> 0
B15: X3B7003656 | C15: Concierge | D15: B/N | E15: 41 | F15: 0.0198 | G15: =+E15*F15 -> 0.8118 | H15: B/N | I15: 44 | J15: 0.0198 | K15: =+I15*J15 -> 0.8712 | L15: B/N | M15: 5 | N15: 0.0198 | O15: =+M15*N15 -> 0.099 | P15: B/N | Q15: 1 | R15: 0.0198 | S15: =+Q15*R15 -> 0.0198 | T15: B/N | V15: 0.0198 | W15: =+U15*V15 -> 0
B16: X3B7003656 | C16: Concierge | D16: Colores | F16: 0.0545 | G16: =+E16*F16 -> 0 | H16: Colores | J16: 0.0545 | K16: =+I16*J16 -> 0 | L16: Colores | M16: 2 | N16: 0.0545 | O16: =+M16*N16 -> 0.109 | P16: Colores | R16: 0.0501 | S16: =+Q16*R16 -> 0 | T16: Colores | V16: 0.0501 | W16: =+U16*V16 -> 0
B17: X3B7003659 | C17: Asistente Gerencia General | D17: B/N | E17: 301 | F17: 0.0198 | G17: =+E17*F17 -> 5.9598 | H17: B/N | I17: 93 | J17: 0.0198 | K17: =+I17*J17 -> 1.8414 | L17: B/N | M17: 134 | N17: 0.0198 | O17: =+M17*N17 -> 2.6532 | P17: B/N | Q17: 101 | R17: 0.0198 | S17: =+Q17*R17 -> 1.9998 | T17: B/N | V17: 0.0198 | W17: =+U17*V17 -> 0
B18: X3B7003659 | C18: Asistente Gerencia General | D18: Colores | E18: 162 | F18: 0.0545 | G18: =+E18*F18 -> 8.829 | H18: Colores | I18: 352 | J18: 0.0545 | K18: =+I18*J18 -> 19.184 | L18: Colores | M18: 245 | N18: 0.0545 | O18: =+M18*N18 -> 13.3525 | P18: Colores | Q18: 141 | R18: 0.0501 | S18: =+Q18*R18 -> 7.0641 | T18: Colores | V18: 0.0501 | W18: =+U18*V18 -> 0
B19: X3B7003660 | C19: Room Service | D19: B/N | E19: 1534 | F19: 0.0198 | G19: =+E19*F19 -> 30.3732 | H19: B/N | I19: 1949 | J19: 0.0198 | K19: =+I19*J19 -> 38.5902 | L19: B/N | M19: 1951 | N19: 0.0198 | O19: =+M19*N19 -> 38.6298 | P19: B/N | Q19: 1831 | R19: 0.0198 | S19: =+Q19*R19 -> 36.2538 | T19: B/N | U19: 1425 | V19: 0.0198 | W19: =+U19*V19 -> 28.215
B20: X3B7003660 | C20: Room Service | D20: Colores | F20: 0.0545 | G20: =+E20*F20 -> 0 | H20: Colores | I20: 1 | J20: 0.0545 | K20: =+I20*J20 -> 0.0545 | L20: Colores | N20: 0.0545 | O20: =+M20*N20 -> 0 | P20: Colores | R20: 0.0501 | S20: =+Q20*R20 -> 0 | T20: Colores | U20: 1 | V20: 0.0501 | W20: =+U20*V20 -> 0.0501
A21: No se usa | B21: X3B7003661 | C21: Disponible | D21: B/N | F21: 0.0198 | G21: =+E21*F21 -> 0 | H21: B/N | I21: 7 | J21: 0.0198 | K21: =+I21*J21 -> 0.1386 | L21: B/N | M21: 2 | N21: 0.0198 | O21: =+M21*N21 -> 0.0396 | P21: B/N | R21: 0.0198 | S21: =+Q21*R21 -> 0 | T21: B/N | V21: 0.0198 | W21: =+U21*V21 -> 0
A22: No se usa | B22: X3B7003661 | C22: Disponible | D22: Colores | E22: 2 | F22: 0.0545 | G22: =+E22*F22 -> 0.109 | H22: Colores | I22: 3 | J22: 0.0545 | K22: =+I22*J22 -> 0.1635 | L22: Colores | N22: 0.0545 | O22: =+M22*N22 -> 0 | P22: Colores | R22: 0.0501 | S22: =+Q22*R22 -> 0 | T22: Colores | V22: 0.0501 | W22: =+U22*V22 -> 0
B23: X3B7003671 | C23: Compras | D23: B/N | E23: 9 | F23: 0.0198 | G23: =+E23*F23 -> 0.1782 | H23: B/N | I23: 20 | J23: 0.0198 | K23: =+I23*J23 -> 0.396 | L23: B/N | M23: 24 | N23: 0.0198 | O23: =+M23*N23 -> 0.4752 | P23: B/N | Q23: 20 | R23: 0.0198 | S23: =+Q23*R23 -> 0.396 | T23: B/N | U23: 15 | V23: 0.0198 | W23: =+U23*V23 -> 0.297
B24: X3B7003671 | C24: Compras | D24: Colores | E24: 25 | F24: 0.0545 | G24: =+E24*F24 -> 1.3625 | H24: Colores | I24: 13 | J24: 0.0545 | K24: =+I24*J24 -> 0.7085 | L24: Colores | M24: 27 | N24: 0.0545 | O24: =+M24*N24 -> 1.4715 | P24: Colores | Q24: 18 | R24: 0.0501 | S24: =+Q24*R24 -> 0.9018 | T24: Colores | U24: 17 | V24: 0.0501 | W24: =+U24*V24 -> 0.8517
B25: X3B7003690 | C25: Cuadres | D25: B/N | F25: 0.0198 | G25: =+E25*F25 -> 0 | H25: B/N | J25: 0.0198 | K25: =+I25*J25 -> 0 | L25: B/N | N25: 0.0198 | O25: =+M25*N25 -> 0 | P25: B/N | R25: 0.0198 | S25: =+Q25*R25 -> 0 | T25: B/N | V25: 0.0198 | W25: =+U25*V25 -> 0
B26: X3B7003690 | C26: Cuadres | D26: Colores | F26: 0.0545 | G26: =+E26*F26 -> 0 | H26: Colores | J26: 0.0545 | K26: =+I26*J26 -> 0 | L26: Colores | N26: 0.0545 | O26: =+M26*N26 -> 0 | P26: Colores | R26: 0.0501 | S26: =+Q26*R26 -> 0 | T26: Colores | V26: 0.0501 | W26: =+U26*V26 -> 0
B27: X3B7003703 | C27: GYM | D27: B/N | E27: 853 | F27: 0.0198 | G27: =+E27*F27 -> 16.8894 | H27: B/N | I27: 921 | J27: 0.0198 | K27: =+I27*J27 -> 18.2358 | L27: B/N | N27: 0.0198 | O27: =+M27*N27 -> 0 | P27: B/N | R27: 0.0198 | S27: =+Q27*R27 -> 0 | T27: B/N | V27: 0.0198 | W27: =+U27*V27 -> 0
B28: X3B7003703 | C28: GYM | D28: Colores | F28: 0.0545 | G28: =+E28*F28 -> 0 | H28: Colores | J28: 0.0545 | K28: =+I28*J28 -> 0 | L28: Colores | M28: 1227 | N28: 0.0545 | O28: =+M28*N28 -> 66.8715 | P28: Colores | Q28: 540 | R28: 0.0501 | S28: =+Q28*R28 -> 27.054 | T28: Colores | V28: 0.0501 | W28: =+U28*V28 -> 0
B29: X3B7003711 | C29: Oficina de Recepción | D29: B/N | E29: 481 | F29: 0.0198 | G29: =+E29*F29 -> 9.5238 | H29: B/N | I29: 529 | J29: 0.0198 | K29: =+I29*J29 -> 10.4742 | L29: B/N | M29: 510 | N29: 0.0198 | O29: =+M29*N29 -> 10.098 | P29: B/N | Q29: 453 | R29: 0.0198 | S29: =+Q29*R29 -> 8.9694 | T29: B/N | U29: 868 | V29: 0.0198 | W29: =+U29*V29 -> 17.1864
B30: X3B7003711 | C30: Oficina de Recepción | D30: Colores | E30: 65 | F30: 0.0545 | G30: =+E30*F30 -> 3.5425 | H30: Colores | I30: 173 | J30: 0.0545 | K30: =+I30*J30 -> 9.4285 | L30: Colores | M30: 28 | N30: 0.0545 | O30: =+M30*N30 -> 1.526 | P30: Colores | Q30: 75 | R30: 0.0501 | S30: =+Q30*R30 -> 3.7575 | T30: Colores | U30: 115 | V30: 0.0501 | W30: =+U30*V30 -> 5.7615
B31: X3B7003712 | C31: Bodegas | D31: B/N | E31: 66 | F31: 0.0198 | G31: =+E31*F31 -> 1.3068 | H31: B/N | I31: 53 | J31: 0.0198 | K31: =+I31*J31 -> 1.0494 | L31: B/N | M31: 80 | N31: 0.0198 | O31: =+M31*N31 -> 1.584 | P31: B/N | Q31: 49 | R31: 0.0198 | S31: =+Q31*R31 -> 0.9702 | T31: B/N | U31: 49 | V31: 0.0198 | W31: =+U31*V31 -> 0.9702
B32: X3B7003712 | C32: Bodegas | D32: Colores | F32: 0.0545 | G32: =+E32*F32 -> 0 | H32: Colores | I32: 2 | J32: 0.0545 | K32: =+I32*J32 -> 0.109 | L32: Colores | N32: 0.0545 | O32: =+M32*N32 -> 0 | P32: Colores | R32: 0.0501 | S32: =+Q32*R32 -> 0 | T32: Colores | V32: 0.0501 | W32: =+U32*V32 -> 0
B33: X3B7003716 | C33: Limpieza | D33: B/N | E33: 22 | F33: 0.0198 | G33: =+E33*F33 -> 0.4356 | H33: B/N | I33: 74 | J33: 0.0198 | K33: =+I33*J33 -> 1.4652 | L33: B/N | M33: 86 | N33: 0.0198 | O33: =+M33*N33 -> 1.7028 | P33: B/N | Q33: 84 | R33: 0.0198 | S33: =+Q33*R33 -> 1.6632 | T33: B/N | U33: 84 | V33: 0.0198 | W33: =+U33*V33 -> 1.6632
B34: X3B7003716 | C34: Limpieza | D34: Colores | F34: 0.0545 | G34: =+E34*F34 -> 0 | H34: Colores | I34: 2 | J34: 0.0545 | K34: =+I34*J34 -> 0.109 | L34: Colores | M34: 540 | N34: 0.0545 | O34: =+M34*N34 -> 29.43 | P34: Colores | R34: 0.0501 | S34: =+Q34*R34 -> 0 | T34: Colores | V34: 0.0501 | W34: =+U34*V34 -> 0
B35: X3B7003751 | C35: Housekeeping | D35: B/N | F35: 0.0198 | G35: =+E35*F35 -> 0 | H35: B/N | I35: 4652 | J35: 0.0198 | K35: =+I35*J35 -> 92.1096 | L35: B/N | M35: 2420 | N35: 0.0198 | O35: =+M35*N35 -> 47.916 | P35: B/N | Q35: 2051 | R35: 0.0198 | S35: =+Q35*R35 -> 40.6098 | T35: B/N | U35: 1788 | V35: 0.0198 | W35: =+U35*V35 -> 35.4024
B36: X3B7003751 | C36: Housekeeping | D36: Colores | F36: 0.0545 | G36: =+E36*F36 -> 0 | H36: Colores | J36: 0.0545 | K36: =+I36*J36 -> 0 | L36: Colores | N36: 0.0545 | O36: =+M36*N36 -> 0 | P36: Colores | R36: 0.0501 | S36: =+Q36*R36 -> 0 | T36: Colores | V36: 0.0501 | W36: =+U36*V36 -> 0
A37: No se usa | B37: X3B7003828 | C37: Disponible | D37: B/N | F37: 0.0198 | G37: =+E37*F37 -> 0 | H37: B/N | J37: 0.0198 | K37: =+I37*J37 -> 0 | L37: B/N | N37: 0.0198 | O37: =+M37*N37 -> 0 | P37: B/N | R37: 0.0198 | S37: =+Q37*R37 -> 0 | T37: B/N | V37: 0.0198 | W37: =+U37*V37 -> 0
A38: No se usa | B38: X3B7003828 | C38: Disponible | D38: Colores | F38: 0.0545 | G38: =+E38*F38 -> 0 | H38: Colores | J38: 0.0545 | K38: =+I38*J38 -> 0 | L38: Colores | N38: 0.0545 | O38: =+M38*N38 -> 0 | P38: Colores | R38: 0.0501 | S38: =+Q38*R38 -> 0 | T38: Colores | V38: 0.0501 | W38: =+U38*V38 -> 0
B39: X3B7003944 | C39: Reservas | D39: B/N | E39: 17 | F39: 0.0198 | G39: =+E39*F39 -> 0.3366 | H39: B/N | J39: 0.0198 | K39: =+I39*J39 -> 0 | L39: B/N | M39: 29 | N39: 0.0198 | O39: =+M39*N39 -> 0.5742 | P39: B/N | Q39: 16 | R39: 0.0198 | S39: =+Q39*R39 -> 0.3168 | T39: B/N | U39: 29 | V39: 0.0198 | W39: =+U39*V39 -> 0.5742
B40: X3B7003944 | C40: Reservas | D40: Colores | F40: 0.0545 | G40: =+E40*F40 -> 0 | H40: Colores | J40: 0.0545 | K40: =+I40*J40 -> 0 | L40: Colores | M40: 5 | N40: 0.0545 | O40: =+M40*N40 -> 0.2725 | P40: Colores | Q40: 5 | R40: 0.0501 | S40: =+Q40*R40 -> 0.2505 | T40: Colores | U40: 1 | V40: 0.0501 | W40: =+U40*V40 -> 0.0501
B41: X3B7003739 | C41: Banquetes | D41: B/N | F41: 0.0198 | G41: =+E41*F41 -> 0 | H41: B/N | J41: 0.0198 | K41: =+I41*J41 -> 0 | L41: B/N | N41: 0.0198 | O41: =+M41*N41 -> 0 | P41: B/N | R41: 0.0198 | S41: =+Q41*R41 -> 0 | T41: B/N | U41: 109 | V41: 0.0198 | W41: =+U41*V41 -> 2.1582
B42: X3B7003739 | C42: Banquetes | D42: Colores | F42: 0.0545 | G42: =+E42*F42 -> 0 | H42: Colores | J42: 0.0545 | K42: =+I42*J42 -> 0 | L42: Colores | N42: 0.0545 | O42: =+M42*N42 -> 0 | P42: Colores | R42: 0.0501 | S42: =+Q42*R42 -> 0 | T42: Colores | U42: 33 | V42: 0.0501 | W42: =+U42*V42 -> 1.6533
B43: MXC300 45000119 | C43: AyB | D43: B/N | E43: 163 | F43: 0.0135 | G43: =+E43*F43 -> 2.2005 | H43: B/N | J43: 0.0135 | K43: =+I43*J43 -> 0 | L43: B/N | N43: 0.0135 | O43: =+M43*N43 -> 0 | P43: B/N | Q43: 153 | R43: 0.0136 | S43: =+Q43*R43 -> 2.0808 | T43: B/N | U43: 395 | V43: 0.0136 | W43: =+U43*V43 -> 5.372
...

Sheet 01
A1: Column1 | B1: Column2 | C1: Column3 | D1: Column4 | E1: Column5 | F1: Column6 | G1: Column7 | H1: Column8 | I1: Column9 | J1: Column10 | K1: Column11 | L1: Column12 | M1: Column13
C2: TOTALES | D2: 3111 | E2: 4213 | M2: =IF(AND(A2<>"",LEFT(A2,3)<>"AV."),A2,M1) -> Column13
A3: XBJZ021745 - WF-C5890 - Bolsa 3 | C3: A4BN | D3: 4141 | E3: 4785 | G3: 644 | H3: 0 | J3: 0 | K3: 0.0168 | L3: 0.00 | M3: =IF(AND(A3<>"",LEFT(A3,3)<>"AV."),A3,M2) -> XBJZ021745 - WF-C5890 - Bolsa 3
A4: AV. VIA CENTRAL 190 CENTRO EMPRESARIAL | C4: A3BN | D4: 0 | E4: 0 | G4: 0 | H4: 0 | J4: 0 | K4: 0.0301 | L4: 0.00 | M4: =IF(AND(A4<>"",LEFT(A4,3)<>"AV."),A4,M3) -> XBJZ021745 - WF-C5890 - Bolsa 3
C5: A4CL | D5: 23586 | E5: 27528 | G5: 3942 | H5: 0 | J5: 0 | K5: 0.0472 | L5: 0.00 | M5: =IF(AND(A5<>"",LEFT(A5,3)<>"AV."),A5,M4) -> XBJZ021745 - WF-C5890 - Bolsa 3
C6: A3CL | D6: 0 | E6: 0 | G6: 0 | H6: 0 | J6: 0 | K6: 0.0906 | L6: 0.00 | M6: =IF(AND(A6<>"",LEFT(A6,3)<>"AV."),A6,M5) -> XBJZ021745 - WF-C5890 - Bolsa 3
C7: TOTALES | D7: 27727 | E7: 32313 | M7: =IF(AND(A7<>"",LEFT(A7,3)<>"AV."),A7,M6) -> XBJZ021745 - WF-C5890 - Bolsa 3
A8: XBJZ027512 - WF-C5890 - Bolsa 3 | C8: A4BN | D8: 3883 | E8: 5188 | G8: 1305 | H8: 0 | J8: 0 | K8: 0.0168 | L8: 0.00 | M8: =IF(AND(A8<>"",LEFT(A8,3)<>"AV."),A8,M7) -> XBJZ027512 - WF-C5890 - Bolsa 3
A9: AV. VIA CENTRAL 190 CENTRO EMPRESARIAL | C9: A3BN | D9: 0 | E9: 0 | G9: 0 | H9: 0 | J9: 0 | K9: 0.0301 | L9: 0.00 | M9: =IF(AND(A9<>"",LEFT(A9,3)<>"AV."),A9,M8) -> XBJZ027512 - WF-C5890 - Bolsa 3
C10: A4CL | D10: 11370 | E10: 15352 | G10: 3982 | H10: 0 | J10: 0 | K10: 0.0472 | L10: 0.00 | M10: =IF(AND(A10<>"",LEFT(A10,3)<>"AV."),A10,M9) -> XBJZ027512 - WF-C5890 - Bolsa 3
C11: A3CL | D11: 0 | E11: 0 | G11: 0 | H11: 0 | J11: 0 | K11: 0.0906 | L11: 0.00 | M11: =IF(AND(A11<>"",LEFT(A11,3)<>"AV."),A11,M10) -> XBJZ027512 - WF-C5890 - Bolsa 3
C12: TOTALES | D12: 15253 | E12: 20540 | M12: =IF(AND(A12<>"",LEFT(A12,3)<>"AV."),A12,M11) -> XBJZ027512 - WF-C5890 - Bolsa 3
A13: 35009304 - MX-3070 - Bolsa 4 | C13: A4BN | D13: 5 | E13: 3848 | G13: 3843 | H13: 0 | J13: 0 | K13: 0.0168 | L13: 0.00 | M13: =IF(AND(A13<>"",LEFT(A13,3)<>"AV."),A13,M12) -> 35009304 - MX-3070 - Bolsa 4
C14: A3BN | D14: 0 | E14: 0 | G14: 0 | H14: 0 | J14: 0 | K14: 0.0301 | L14: 0.00 | M14: =IF(AND(A14<>"",LEFT(A14,3)<>"AV."),A14,M13) -> 35009304 - MX-3070 - Bolsa 4
C15: A4CL | D15: 31 | E15: 340 | G15: 309 | H15: 0 | J15: 0 | K15: 0.0472 | L15: 0.00 | M15: =IF(AND(A15<>"",LEFT(A15,3)<>"AV."),A15,M14) -> 35009304 - MX-3070 - Bolsa 4
C16: A3CL | D16: 0 | E16: 0 | G16: 0 | H16: 0 | J16: 0 | K16: 0.0906 | L16: 0.00 | M16: =IF(AND(A16<>"",LEFT(A16,3)<>"AV."),A16,M15) -> 35009304 - MX-3070 - Bolsa 4
C17: TOTALES | D17: 36 | E17: 4188 | M17: =IF(AND(A17<>"",LEFT(A17,3)<>"AV."),A17,M16) -> 35009304 - MX-3070 - Bolsa 4
A18: 35E33608 - IR-1643 - Bolsa 1 | C18: A4BN | D18: 36 | E18: 23904 | G18: 23868 | H18: 0 | J18: 0 | K18: 0.0168 | L18: 0.00 | M18: =IF(AND(A18<>"",LEFT(A18,3)<>"AV."),A18,M17) -> 35E33608 - IR-1643 - Bolsa 1
A19: AV. SANTO TORIBIO NRO 173 URB ROSARIO (V | C19: A3BN | D19: 0 | E19: 0 | G19: 0 | H19: 0 | J19: 0 | K19: 0.0301 | L19: 0.00 | M19: =IF(AND(A19<>"",LEFT(A19,3)<>"AV."),A19,M18) -> 35E33608 - IR-1643 - Bolsa 1
C20: A4CL | D20: 0 | E20: 0 | G20: 0 | H20: 0 | J20: 0 | K20: 0.0472 | L20: 0.00 | M20: =IF(AND(A20<>"",LEFT(A20,3)<>"AV."),A20,M19) -> 35E33608 - IR-1643 - Bolsa 1
C21: A3CL | D21: 0 | E21: 0 | G21: 0 | H21: 0 | J21: 0 | K21: 0.0906 | L21: 0.00 | M21: =IF(AND(A21<>"",LEFT(A21,3)<>"AV."),A21,M20) -> 35E33608 - IR-1643 - Bolsa 1
C22: TOTALES | D22: 36 | E22: 23904 | M22: =IF(AND(A22<>"",LEFT(A22,3)<>"AV."),A22,M21) -> 35E33608 - IR-1643 - Bolsa 1
A23: 35E33607 - IR-1643 - Bolsa 1 | C23: A4BN | D23: 6528 | E23: 14888 | G23: 8360 | H23: 0 | J23: 0 | K23: 0.0168 | L23: 0.00 | M23: =IF(AND(A23<>"",LEFT(A23,3)<>"AV."),A23,M22) -> 35E33607 - IR-1643 - Bolsa 1
A24: AV. SANTO TORIBIO NRO 173 URB ROSARIO (VIA CENTRO | C24: A3BN | D24: 0 | E24: 0 | G24: 0 | H24: 0 | J24: 0 | K24: 0.0301 | L24: 0.00 | M24: =IF(AND(A24<>"",LEFT(A24,3)<>"AV."),A24,M23) -> 35E33607 - IR-1643 - Bolsa 1
C25: A4CL | D25: 0 | E25: 0 | G25: 0 | H25: 0 | J25: 0 | K25: 0.0472 | L25: 0.00 | M25: =IF(AND(A25<>"",LEFT(A25,3)<>"AV."),A25,M24) -> 35E33607 - IR-1643 - Bolsa 1
C26: A3CL | D26: 0 | E26: 0 | G26: 0 | H26: 0 | J26: 0 | K26: 0.0906 | L26: 0.00 | M26: =IF(AND(A26<>"",LEFT(A26,3)<>"AV."),A26,M25) -> 35E33607 - IR-1643 - Bolsa 1
C27: TOTALES | D27: 6528 | E27: 14888 | M27: =IF(AND(A27<>"",LEFT(A27,3)<>"AV."),A27,M26) -> 35E33607 - IR-1643 - Bolsa 1
A28: RJQ00596 - IR-C3330 - Bolsa 5 | C28: A4BN | D28: 130708 | E28: 131063 | G28: 355 | H28: 0 | J28: 0 | K28: 0.0168 | L28: 0.00 | M28: =IF(AND(A28<>"",LEFT(A28,3)<>"AV."),A28,M27) -> RJQ00596 - IR-C3330 - Bolsa 5
A29: AV. VIA CENTRAL 190 CENTRO EMPRESARIAL | C29: A3BN | D29: 6966 | E29: 6966 | G29: 0 | H29: 0 | J29: 0 | K29: 0.0301 | L29: 0.00 | M29: =IF(AND(A29<>"",LEFT(A29,3)<>"AV."),A29,M28) -> RJQ00596 - IR-C3330 - Bolsa 5
C30: A4CL | D30: 187880 | E30: 188332 | G30: 452 | H30: 0 | J30: 0 | K30: 0.0472 | L30: 0.00 | M30: =IF(AND(A30<>"",LEFT(A30,3)<>"AV."),A30,M29) -> RJQ00596 - IR-C3330 - Bolsa 5
C31: A3CL | D31: 6966 | E31: 6970 | G31: 4 | H31: 0 | J31: 0 | K31: 0.0906 | L31: 0.00 | M31: =IF(AND(A31<>"",LEFT(A31,3)<>"AV."),A31,M30) -> RJQ00596 - IR-C3330 - Bolsa 5
C32: TOTALES | D32: 332520 | E32: 333331 | M32: =IF(AND(A32<>"",LEFT(A32,3)<>"AV."),A32,M31) -> RJQ00596 - IR-C3330 - Bolsa 5
A33: BOLSA N° #1 | C33: FORMATOS | F33: VOLUMEN MAXIMO ESTABLECIDO | I33: VOLUMEN EXCEDENTE A LO ESTABLECIDO | K33: VALOR UNIDAD EXCEDENTE | L33: MONTO TOTAL EXCEDENTE | M33: =IF(AND(A33<>"",LEFT(A33,3)<>"AV."),A33,M32) -> BOLSA N° #1
C34: A4BN | D34: 43216 | F34: 13000 | I34: 30216 | K34: 0.0168 | L34: 507.63 | M34: =IF(AND(A34<>"",LEFT(A34,3)<>"AV."),A34,M33) -> BOLSA N° #1
C35: A3BN | D35: 0 | F35: 0 | I35: 0 | K35: 0.0301 | L35: 0.00 | M35: =IF(AND(A35<>"",LEFT(A35,3)<>"AV."),A35,M34) -> BOLSA N° #1
C36: A4CL | D36: 0 | F36: 0 | I36: 0 | K36: 0.0472 | L36: 0.00 | M36: =IF(AND(A36<>"",LEFT(A36,3)<>"AV."),A36,M35) -> BOLSA N° #1
C37: A3CL | D37: 0 | F37: 0 | I37: 0 | K37: 0.0906 | L37: 0.00 | M37: =IF(AND(A37<>"",LEFT(A37,3)<>"AV."),A37,M36) -> BOLSA N° #1
A38: BOLSA N° #2 | C38: FORMATOS | F38: VOLUMEN MAXIMO ESTABLECIDO | I38: VOLUMEN EXCEDENTE A LO ESTABLECIDO | K38: VALOR UNIDAD EXCEDENTE | L38: MONTO TOTAL EXCEDENTE | M38: =IF(AND(A38<>"",LEFT(A38,3)<>"AV."),A38,M37) -> BOLSA N° #2
C39: A4BN | D39: 9567 | F39: 1504 | I39: 8063 | K39: 0.0168 | L39: 135.46 | M39: =IF(AND(A39<>"",LEFT(A39,3)<>"AV."),A39,M38) -> BOLSA N° #2
C40: A3BN | D40: 0 | F40: 0 | I40: 0 | K40: 0.0301 | L40: 0.00 | M40: =IF(AND(A40<>"",LEFT(A40,3)<>"AV."),A40,M39) -> BOLSA N° #2
...

Sheet 02
A1: Column1 | B1: Column2 | C1: Column3 | D1: Column4 | E1: Column5 | F1: Column6 | G1: Column7 | H1: Column8 | I1: Column9 | J1: Column10
A2: [image] | B2: CUADRO DE CONSUMO DEL CONTRATO 276580 PERIODO 2026 MES DE MARZO | J2: =IF(AND(A2<>"",LEFT(A2,3)<>"AV."),A2,J1) -> [image]
A3: HOTELERA COSTA DEL PACIFICO S.A. - | B3: (C20297885538) | J3: =IF(AND(A3<>"",LEFT(A3,3)<>"AV."),A3,J2) -> HOTELERA COSTA DEL PACIFICO S.A. -
A4: EQUIPO | B4: FORMATOS | J4: =IF(AND(A4<>"",LEFT(A4,3)<>"AV."),A4,J3) -> EQUIPO
A5: GRUPO: SIN BOLSA SEGUN CONTRATO VIGENTE | J5: =IF(AND(A5<>"",LEFT(A5,3)<>"AV."),A5,J4) -> GRUPO: SIN BOLSA SEGUN CONTRATO VIGENTE
A6: X3B7003661 - WF-C5790 | B6: A4BN | C6: 13075 | D6: 20147 | E6: 7072 | F6: 0 | G6: 7072 | H6: 0.0168 | I6: 118.81 | J6: =IF(AND(A6<>"",LEFT(A6,3)<>"AV."),A6,J5) -> X3B7003661 - WF-C5790
A7: AV. VIA CENTRAL 190 CENTRO EMPRESARIAL | B7: A3BN | C7: 0 | D7: 0 | E7: 0 | F7: 0 | G7: 0 | H7: 0.0301 | I7: 0 | J7: =IF(AND(A7<>"",LEFT(A7,3)<>"AV."),A7,J6) -> X3B7003661 - WF-C5790
B8: A4CL | C8: 6457 | D8: 13206 | E8: 6749 | F8: 0 | G8: 6749 | H8: 0.0472 | I8: 318.55 | J8: =IF(AND(A8<>"",LEFT(A8,3)<>"AV."),A8,J7) -> X3B7003661 - WF-C5790
B9: A3CL | C9: 0 | D9: 0 | E9: 0 | F9: 0 | G9: 0 | H9: 0.0906 | I9: 0 | J9: =IF(AND(A9<>"",LEFT(A9,3)<>"AV."),A9,J8) -> X3B7003661 - WF-C5790
B10: TOTALES | C10: 19532 | D10: 33353 | J10: =IF(AND(A10<>"",LEFT(A10,3)<>"AV."),A10,J9) -> X3B7003661 - WF-C5790
A11: 9502370Y - MX-M3070 - Bolsa 1 | B11: A4BN | C11: 57 | D11: 8633 | E11: 8576 | F11: 0 | G11: 0 | H11: 0.0168 | I11: 0 | J11: =IF(AND(A11<>"",LEFT(A11,3)<>"AV."),A11,J10) -> 9502370Y - MX-M3070 - Bolsa 1
A12: AV. SANTO TORIBIO NRO 173 URB ROSARIO (VIA CENTRO | B12: A3BN | C12: 0 | D12: 0 | E12: 0 | F12: 0 | G12: 0 | H12: 0.0301 | I12: 0 | J12: =IF(AND(A12<>"",LEFT(A12,3)<>"AV."),A12,J11) -> 9502370Y - MX-M3070 - Bolsa 1
B13: A4CL | C13: 0 | D13: 0 | E13: 0 | F13: 0 | G13: 0 | H13: 0.0472 | I13: 0 | J13: =IF(AND(A13<>"",LEFT(A13,3)<>"AV."),A13,J12) -> 9502370Y - MX-M3070 - Bolsa 1
B14: A3CL | C14: 0 | D14: 0 | E14: 0 | F14: 0 | G14: 0 | H14: 0.0906 | I14: 0 | J14: =IF(AND(A14<>"",LEFT(A14,3)<>"AV."),A14,J13) -> 9502370Y - MX-M3070 - Bolsa 1
B15: TOTALES | C15: 57 | D15: 8633 | J15: =IF(AND(A15<>"",LEFT(A15,3)<>"AV."),A15,J14) -> 9502370Y - MX-M3070 - Bolsa 1
A16: QFX06245 - IR-1730 - Bolsa 1 | B16: A4BN | C16: 156715 | D16: 159127 | E16: 2412 | F16: 0 | G16: 0 | H16: 0.0168 | I16: 0 | J16: =IF(AND(A16<>"",LEFT(A16,3)<>"AV."),A16,J15) -> QFX06245 - IR-1730 - Bolsa 1
A17: AV. SANTO TORIBIO NRO 173 URB ROSARIO (VIA CENTRO | B17: A3BN | C17: 0 | D17: 0 | E17: 0 | F17: 0 | G17: 0 | H17: 0.0301 | I17: 0 | J17: =IF(AND(A17<>"",LEFT(A17,3)<>"AV."),A17,J16) -> QFX06245 - IR-1730 - Bolsa 1
B18: A4CL | C18: 0 | D18: 0 | E18: 0 | F18: 0 | G18: 0 | H18: 0.0472 | I18: 0 | J18: =IF(AND(A18<>"",LEFT(A18,3)<>"AV."),A18,J17) -> QFX06245 - IR-1730 - Bolsa 1
B19: A3CL | C19: 0 | D19: 0 | E19: 0 | F19: 0 | G19: 0 | H19: 0.0906 | I19: 0 | J19: =IF(AND(A19<>"",LEFT(A19,3)<>"AV."),A19,J18) -> QFX06245 - IR-1730 - Bolsa 1
B20: TOTALES | C20: 156715 | D20: 159127 | J20: =IF(AND(A20<>"",LEFT(A20,3)<>"AV."),A20,J19) -> QFX06245 - IR-1730 - Bolsa 1
A21: X3B7002433 - WF-C5790 - Bolsa 2 | B21: A4BN | C21: 83734 | D21: 84608 | E21: 874 | F21: 0 | G21: 0 | H21: 0.0168 | I21: 0 | J21: =IF(AND(A21<>"",LEFT(A21,3)<>"AV."),A21,J20) -> X3B7002433 - WF-C5790 - Bolsa 2
A22: AV. VIA CENTRAL 190 CENTRO EMPRESARIAL | B22: A3BN | C22: 0 | D22: 0 | E22: 0 | F22: 0 | G22: 0 | H22: 0.0301 | I22: 0 | J22: =IF(AND(A22<>"",LEFT(A22,3)<>"AV."),A22,J21) -> X3B7002433 - WF-C5790 - Bolsa 2
B23: A4CL | C23: 21349 | D23: 25358 | E23: 4009 | F23: 0 | G23: 0 | H23: 0.0472 | I23: 0 | J23: =IF(AND(A23<>"",LEFT(A23,3)<>"AV."),A23,J22) -> X3B7002433 - WF-C5790 - Bolsa 2
B24: A3CL | C24: 0 | D24: 0 | E24: 0 | F24: 0 | G24: 0 | H24: 0.0906 | I24: 0 | J24: =IF(AND(A24<>"",LEFT(A24,3)<>"AV."),A24,J23) -> X3B7002433 - WF-C5790 - Bolsa 2
B25: TOTALES | C25: 105083 | D25: 109966 | J25: =IF(AND(A25<>"",LEFT(A25,3)<>"AV."),A25,J24) -> X3B7002433 - WF-C5790 - Bolsa 2
A26: X3B7003876 - WF-C5790 - Bolsa 2 | B26: A4BN | C26: 58830 | D26: 59665 | E26: 835 | F26: 0 | G26: 0 | H26: 0.0168 | I26: 0 | J26: =IF(AND(A26<>"",LEFT(A26,3)<>"AV."),A26,J25) -> X3B7003876 - WF-C5790 - Bolsa 2
A27: AV. VIA CENTRAL 190 CENTRO EMPRESARIAL | B27: A3BN | C27: 0 | D27: 0 | E27: 0 | F27: 0 | G27: 0 | H27: 0.0301 | I27: 0 | J27: =IF(AND(A27<>"",LEFT(A27,3)<>"AV."),A27,J26) -> X3B7003876 - WF-C5790 - Bolsa 2
B28: A4CL | C28: 35550 | D28: 36043 | E28: 493 | F28: 0 | G28: 0 | H28: 0.0472 | I28: 0 | J28: =IF(AND(A28<>"",LEFT(A28,3)<>"AV."),A28,J27) -> X3B7003876 - WF-C5790 - Bolsa 2
B29: A3CL | C29: 0 | D29: 0 | E29: 0 | F29: 0 | G29: 0 | H29: 0.0906 | I29: 0 | J29: =IF(AND(A29<>"",LEFT(A29,3)<>"AV."),A29,J28) -> X3B7003876 - WF-C5790 - Bolsa 2
B30: TOTALES | C30: 94380 | D30: 95708 | J30: =IF(AND(A30<>"",LEFT(A30,3)<>"AV."),A30,J29) -> X3B7003876 - WF-C5790 - Bolsa 2
A31: X3B7003659 - WF-C5790 - Bolsa 2 | B31: A4BN | C31: 15527 | D31: 15992 | E31: 465 | F31: 0 | G31: 0 | H31: 0.0168 | I31: 0 | J31: =IF(AND(A31<>"",LEFT(A31,3)<>"AV."),A31,J30) -> X3B7003659 - WF-C5790 - Bolsa 2
A32: AV. SANTO TORIBIO NRO 173 URB ROSARIO (VIA CENTRO | B32: A3BN | C32: 0 | D32: 0 | E32: 0 | F32: 0 | G32: 0 | H32: 0.0301 | I32: 0 | J32: =IF(AND(A32<>"",LEFT(A32,3)<>"AV."),A32,J31) -> X3B7003659 - WF-C5790 - Bolsa 2
B33: A4CL | C33: 14379 | D33: 15205 | E33: 826 | F33: 0 | G33: 0 | H33: 0.0472 | I33: 0 | J33: =IF(AND(A33<>"",LEFT(A33,3)<>"AV."),A33,J32) -> X3B7003659 - WF-C5790 - Bolsa 2
B34: A3CL | C34: 0 | D34: 0 | E34: 0 | F34: 0 | G34: 0 | H34: 0.0906 | I34: 0 | J34: =IF(AND(A34<>"",LEFT(A34,3)<>"AV."),A34,J33) -> X3B7003659 - WF-C5790 - Bolsa 2
B35: TOTALES | C35: 29906 | D35: 31197 | J35: =IF(AND(A35<>"",LEFT(A35,3)<>"AV."),A35,J34) -> X3B7003659 - WF-C5790 - Bolsa 2
A36: X3B7003660 - WF-C5790 - Bolsa 2 | B36: A4BN | C36: 83188 | D36: 83943 | E36: 755 | F36: 0 | G36: 0 | H36: 0.0168 | I36: 0 | J36: =IF(AND(A36<>"",LEFT(A36,3)<>"AV."),A36,J35) -> X3B7003660 - WF-C5790 - Bolsa 2
A37: AV. SANTO TORIBIO NRO 173 URB ROSARIO (VIA CENTRO | B37: A3BN | C37: 0 | D37: 0 | E37: 0 | F37: 0 | G37: 0 | H37: 0.0301 | I37: 0 | J37: =IF(AND(A37<>"",LEFT(A37,3)<>"AV."),A37,J36) -> X3B7003660 - WF-C5790 - Bolsa 2
B38: A4CL | C38: 18110 | D38: 20208 | E38: 2098 | F38: 0 | G38: 0 | H38: 0.0472 | I38: 0 | J38: =IF(AND(A38<>"",LEFT(A38,3)<>"AV."),A38,J37) -> X3B7003660 - WF-C5790 - Bolsa 2
B39: A3CL | C39: 0 | D39: 0 | E39: 0 | F39: 0 | G39: 0 | H39: 0.0906 | I39: 0 | J39: =IF(AND(A39<>"",LEFT(A39,3)<>"AV."),A39,J38) -> X3B7003660 - WF-C5790 - Bolsa 2
B40: TOTALES | C40: 101298 | D40: 104151 | J40: =IF(AND(A40<>"",LEFT(A40,3)<>"AV."),A40,J39) -> X3B7003660 - WF-C5790 - Bolsa 2
...

Sheet 2026-3
A1: 46112 | B1: Marca | C1: Modelo | D1: S/N | E1: IP | F1: Observación | G1: Cantidad Impresoras | H1: Bolsa | I1: Formatos | J1: Contador Inicial | K1: Contador Final | L1: Consumo del Mes | M1: Volumen Maximo Establecido | N1: Volumen Excedente | O1: Precio | P1: Total | Q1: alquiler fijo | T1: centro costo | V1: Bolsa | W1: Formatos | X1: Volumen Maximo
B2: Canon | C2: IR-C3330 | D2: RJQ00596 | E2: 10.72.8.203 | F2: 2do Piso - Seguridad | G2: 1 | H2: Bolsa 5 | I2: A4BN | J2: =+SUMIFS('01'!$D:$D,'01'!$M:$M,$D$2&" - "&$C$2&" - "&$H$2,'01'!$C:$C,'2026-3'!$I2) -> 130708 | K2: =+SUMIFS('01'!$E:$E,'01'!$M:$M,$D$2&" - "&$C$2&" - "&$H$2,'01'!$C:$C,'2026-3'!$I2) -> 131063 | L2: =IF(K2-J2<=0,"0",K2-J2) -> 355 | M2: =SUMIFS(X:X,V:V,H$18,W:W,I2)/COUNTIF(H:H,H$18) -> 188 | N2: =IFERROR(+L2-M2,"") -> 167 | O2: =VALUE(+VLOOKUP(I2,'01'!C:K,9,FALSE)) -> 0.0168 | P2: =IFERROR(+N2*O2,"") -> 2.8056 | Q2: {=_xlfn._xlws.FILTER(SAP!$B$2,1)/COUNTA($G$2:$G$85)} -> 51.681905 | R2: =+SUM(P2:P5) -> -2.0712 | S2: 941231308 | T2: 408 | U2: 1 | V2: Bolsa 1 | W2: A4BN | X2: 13000
I3: A3BN | J3: =+SUMIFS('01'!$D:$D,'01'!$M:$M,$D$2&" - "&$C$2&" - "&$H$2,'01'!$C:$C,'2026-3'!$I3) -> 6966 | K3: =+SUMIFS('01'!$E:$E,'01'!$M:$M,$D$2&" - "&$C$2&" - "&$H$2,'01'!$C:$C,'2026-3'!$I3) -> 6966 | L3: =IF(K3-J3<=0,"0",K3-J3) -> 0 | M3: =SUMIFS(X:X,V:V,H$18,W:W,I3)/COUNTIF(H:H,H$18) -> 0 | N3: =IFERROR(+L3-M3,"") -> 0 | O3: =VALUE(+VLOOKUP(I3,'01'!C:K,9,FALSE)) -> 0.0301 | P3: =IFERROR(+N3*O3,"") -> 0 | V3: Bolsa 1 | W3: A3BN
I4: A4CL | J4: =+SUMIFS('01'!$D:$D,'01'!$M:$M,$D$2&" - "&$C$2&" - "&$H$2,'01'!$C:$C,'2026-3'!$I4) -> 187880 | K4: =+SUMIFS('01'!$E:$E,'01'!$M:$M,$D$2&" - "&$C$2&" - "&$H$2,'01'!$C:$C,'2026-3'!$I4) -> 188332 | L4: =IF(K4-J4<=0,"0",K4-J4) -> 452 | M4: =SUMIFS(X:X,V:V,H$18,W:W,I4)/COUNTIF(H:H,H$18) -> 563 | N4: =IFERROR(+L4-M4,"") -> -111 | O4: =VALUE(+VLOOKUP(I4,'01'!C:K,9,FALSE)) -> 0.0472 | P4: =IFERROR(+N4*O4,"") -> -5.2392 | V4: Bolsa 1 | W4: A4CL
I5: A3CL | J5: =+SUMIFS('01'!$D:$D,'01'!$M:$M,$D$2&" - "&$C$2&" - "&$H$2,'01'!$C:$C,'2026-3'!$I5) -> 6966 | K5: =+SUMIFS('01'!$E:$E,'01'!$M:$M,$D$2&" - "&$C$2&" - "&$H$2,'01'!$C:$C,'2026-3'!$I5) -> 6970 | L5: =IF(K5-J5<=0,"0",K5-J5) -> 4 | M5: =SUMIFS(X:X,V:V,H$18,W:W,I5)/COUNTIF(H:H,H$18) -> 0 | N5: =IFERROR(+L5-M5,"") -> 4 | O5: =VALUE(+VLOOKUP(I5,'01'!C:K,9,FALSE)) -> 0.0906 | P5: =IFERROR(+N5*O5,"") -> 0.3624 | V5: Bolsa 1 | W5: A3CL
C6: IR-1730 | D6: QFX06245 | E6: 10.72.8.215 | F6: 2do Piso - Oficina Auditor de Ingresos | G6: 1 | H6: Bolsa 1 | I6: A4BN | J6: =+SUMIFS('02'!C:C,'02'!J:J,D6&" - "&C6&" - "&H6,'02'!B:B,'2026-3'!$I6) -> 156715 | K6: =+SUMIFS('02'!D:D,'02'!J:J,D6&" - "&C6&" - "&H6,'02'!B:B,'2026-3'!$I6) -> 159127 | L6: =IF(K6-J6<=0,"0",K6-J6) -> 2412 | M6: =SUMIFS(X:X,V:V,H6,W:W,I6)/COUNTIF(H:H,H6) -> 3250 | N6: =IFERROR(+L6-M6,"") -> -838 | O6: =VALUE(+VLOOKUP(I6,'01'!C:K,9,FALSE)) -> 0.0168 | P6: =+N6*O6 -> -14.0784 | Q6: {=_xlfn._xlws.FILTER(SAP!$B$2,1)/COUNTA($G$2:$G$85)} -> 51.681905 | R6: =+SUM(P6:P9) -> -14.0784 | S6: 941231308 | T6: 403 | U6: 2 | V6: Bolsa 2 | W6: A4BN | X6: 1504 | Y6: =+COUNTIF(H:H,V6) -> 8
I7: A3BN | J7: =+SUMIFS('02'!C:C,'02'!J:J,D6&" - "&C6&" - "&H6,'02'!B:B,'2026-3'!$I7) -> 0 | K7: =+SUMIFS('02'!D:D,'02'!J:J,D6&" - "&C6&" - "&H6,'02'!B:B,'2026-3'!$I7) -> 0 | L7: =IF(K7-J7<=0,"0",K7-J7) -> 0 | N7: =IFERROR(+L7-M7,"") -> 0 | O7: =VALUE(+VLOOKUP(I7,'01'!C:K,9,FALSE)) -> 0.0301 | P7: =+N7*O7 -> 0 | V7: Bolsa 2 | W7: A3BN
I8: A4CL | J8: =+SUMIFS('02'!C:C,'02'!J:J,D6&" - "&C6&" - "&H6,'02'!B:B,'2026-3'!$I8) -> 0 | K8: =+SUMIFS('02'!D:D,'02'!J:J,D6&" - "&C6&" - "&H6,'02'!B:B,'2026-3'!$I8) -> 0 | L8: =IF(K8-J8<=0,"0",K8-J8) -> 0 | N8: =IFERROR(+L8-M8,"") -> 0 | O8: =VALUE(+VLOOKUP(I8,'01'!C:K,9,FALSE)) -> 0.0472 | P8: =+N8*O8 -> 0 | V8: Bolsa 2 | W8: A4CL | X8: 4504 | Y8: =+X6/Y6 -> 188
I9: A3CL | J9: =+SUMIFS('02'!C:C,'02'!J:J,D6&" - "&C6&" - "&H6,'02'!B:B,'2026-3'!$I9) -> 0 | K9: =+SUMIFS('02'!D:D,'02'!J:J,D6&" - "&C6&" - "&H6,'02'!B:B,'2026-3'!$I9) -> 0 | L9: =IF(K9-J9<=0,"0",K9-J9) -> 0 | N9: =IFERROR(+L9-M9,"") -> 0 | O9: =VALUE(+VLOOKUP(I9,'01'!C:K,9,FALSE)) -> 0.0906 | P9: =+N9*O9 -> 0 | V9: Bolsa 2 | W9: A3CL
C10: IR-1643 | D10: 35E33608 | E10: 10.72.8.211 | F10: 1er Piso - Front Desk - Recepción | G10: 1 | H10: Bolsa 1 | I10: A4BN | J10: =+SUMIFS('01'!$D:$D,'01'!$M:$M,$D$10&" - "&$C$10&" - "&$H$10,'01'!$C:$C,'2026-3'!$I10) -> 36 | K10: =+SUMIFS('01'!$E:$E,'01'!$M:$M,$D$10&" - "&$C$10&" - "&$H$10,'01'!$C:$C,'2026-3'!$I10) -> 23904 | L10: =IF(K10-J10<=0,"0",K10-J10) -> 23868 | M10: =SUMIFS(X:X,V:V,H10,W:W,I10)/COUNTIF(H:H,H10) -> 3250 | N10: =IFERROR(+L10-M10,"") -> 20618 | O10: =VALUE(+VLOOKUP(I10,'01'!C:K,9,FALSE)) -> 0.0168 | P10: =+N10*O10 -> 346.3824 | Q10: {=_xlfn._xlws.FILTER(SAP!$B$2,1)/COUNTA($G$2:$G$85)} -> 51.681905 | R10: =+SUM(P10:P13) -> 346.3824 | S10: 931221108 | T10: 101 | U10: 1 | V10: Bolsa 3 | W10: A4BN | X10: 1128
I11: A3BN | J11: =+SUMIFS('01'!$D:$D,'01'!$M:$M,$D$10&" - "&$C$10&" - "&$H$10,'01'!$C:$C,'2026-3'!$I11) -> 0 | K11: =+SUMIFS('01'!$E:$E,'01'!$M:$M,$D$10&" - "&$C$10&" - "&$H$10,'01'!$C:$C,'2026-3'!$I11) -> 0 | L11: =IF(K11-J11<=0,"0",K11-J11) -> 0 | N11: =IFERROR(+L11-M11,"") -> 0 | O11: =VALUE(+VLOOKUP(I11,'01'!C:K,9,FALSE)) -> 0.0301 | P11: =+N11*O11 -> 0 | V11: Bolsa 3 | W11: A3BN
I12: A4CL | J12: =+SUMIFS('01'!$D:$D,'01'!$M:$M,$D$10&" - "&$C$10&" - "&$H$10,'01'!$C:$C,'2026-3'!$I12) -> 0 | K12: =+SUMIFS('01'!$E:$E,'01'!$M:$M,$D$10&" - "&$C$10&" - "&$H$10,'01'!$C:$C,'2026-3'!$I12) -> 0 | L12: =IF(K12-J12<=0,"0",K12-J12) -> 0 | N12: =IFERROR(+L12-M12,"") -> 0 | O12: =VALUE(+VLOOKUP(I12,'01'!C:K,9,FALSE)) -> 0.0472 | P12: =+N12*O12 -> 0 | V12: Bolsa 3 | W12: A4CL | X12: 3378
I13: A3CL | J13: =+SUMIFS('01'!$D:$D,'01'!$M:$M,$D$10&" - "&$C$10&" - "&$H$10,'01'!$C:$C,'2026-3'!$I13) -> 0 | K13: =+SUMIFS('01'!$E:$E,'01'!$M:$M,$D$10&" - "&$C$10&" - "&$H$10,'01'!$C:$C,'2026-3'!$I13) -> 0 | L13: =IF(K13-J13<=0,"0",K13-J13) -> 0 | N13: =IFERROR(+L13-M13,"") -> 0 | O13: =VALUE(+VLOOKUP(I13,'01'!C:K,9,FALSE)) -> 0.0906 | P13: =+N13*O13 -> 0 | V13: Bolsa 3 | W13: A3CL
C14: IR-1643 | D14: 35E33607 | E14: 10.72.8.153 | F14: 1er Piso - Front Desk - Recepción | G14: 1 | H14: Bolsa 1 | I14: A4BN | J14: =+SUMIFS('01'!$D:$D,'01'!$M:$M,$D$14&" - "&$C$14&" - "&$H$14,'01'!$C:$C,'2026-3'!$I14) -> 6528 | K14: =+SUMIFS('01'!$E:$E,'01'!$M:$M,$D$14&" - "&$C$14&" - "&$H$14,'01'!$C:$C,'2026-3'!$I14) -> 14888 | L14: =IF(K14-J14<=0,"0",K14-J14) -> 8360 | M14: =SUMIFS(X:X,V:V,H14,W:W,I14)/COUNTIF(H:H,H14) -> 3250 | N14: =IFERROR(+L14-M14,"") -> 5110 | O14: =VALUE(+VLOOKUP(I14,'01'!C:K,9,FALSE)) -> 0.0168 | P14: =+N14*O14 -> 85.848 | Q14: {=_xlfn._xlws.FILTER(SAP!$B$2,1)/COUNTA($G$2:$G$85)} -> 51.681905 | R14: =+SUM(P14:P17) -> 85.848 | S14: 931221108 | T14: 101 | U14: 1 | V14: Bolsa 4 | W14: A4BN | X14: 188
I15: A3BN | J15: =+SUMIFS('01'!$D:$D,'01'!$M:$M,$D$14&" - "&$C$14&" - "&$H$14,'01'!$C:$C,'2026-3'!$I15) -> 0 | K15: =+SUMIFS('01'!$E:$E,'01'!$M:$M,$D$14&" - "&$C$14&" - "&$H$14,'01'!$C:$C,'2026-3'!$I15) -> 0 | L15: =IF(K15-J15<=0,"0",K15-J15) -> 0 | N15: =IFERROR(+L15-M15,"") -> 0 | O15: =VALUE(+VLOOKUP(I15,'01'!C:K,9,FALSE)) -> 0.0301 | P15: =+N15*O15 -> 0 | V15: Bolsa 4 | W15: A3BN
I16: A4CL | J16: =+SUMIFS('01'!$D:$D,'01'!$M:$M,$D$14&" - "&$C$14&" - "&$H$14,'01'!$C:$C,'2026-3'!$I16) -> 0 | K16: =+SUMIFS('01'!$E:$E,'01'!$M:$M,$D$14&" - "&$C$14&" - "&$H$14,'01'!$C:$C,'2026-3'!$I16) -> 0 | L16: =IF(K16-J16<=0,"0",K16-J16) -> 0 | N16: =IFERROR(+L16-M16,"") -> 0 | O16: =VALUE(+VLOOKUP(I16,'01'!C:K,9,FALSE)) -> 0.0472 | P16: =+N16*O16 -> 0 | V16: Bolsa 4 | W16: A4CL | X16: 563
I17: A3CL | J17: =+SUMIFS('01'!$D:$D,'01'!$M:$M,$D$14&" - "&$C$14&" - "&$H$14,'01'!$C:$C,'2026-3'!$I17) -> 0 | K17: =+SUMIFS('01'!$E:$E,'01'!$M:$M,$D$14&" - "&$C$14&" - "&$H$14,'01'!$C:$C,'2026-3'!$I17) -> 0 | L17: =IF(K17-J17<=0,"0",K17-J17) -> 0 | N17: =IFERROR(+L17-M17,"") -> 0 | O17: =VALUE(+VLOOKUP(I17,'01'!C:K,9,FALSE)) -> 0.0906 | P17: =+N17*O17 -> 0 | V17: Bolsa 4 | W17: A3CL
B18: Epson | C18: WF-C5790 | D18: X3B7002433 | E18: 10.72.8.191 | F18: 2do Piso - Oficina Banquetes | G18: 1 | H18: Bolsa 2 | I18: A4BN | J18: =+SUMIFS('02'!C:C,'02'!J:J,D18&" - "&C18&" - "&H18,'02'!B:B,'2026-3'!$I18) -> 83734 | K18: =+SUMIFS('02'!D:D,'02'!J:J,D18&" - "&C18&" - "&H18,'02'!B:B,'2026-3'!$I18) -> 84608 | L18: =IF(K18-J18<=0,"0",K18-J18) -> 874 | M18: =SUMIFS(X:X,V:V,H$18,W:W,I18)/COUNTIF(H:H,H$18) -> 188 | N18: =IFERROR(+L18-M18,"") -> 686 | O18: =VALUE(+VLOOKUP(I18,'01'!C:K,9,FALSE)) -> 0.0168 | P18: =+N18*O18 -> 11.5248 | Q18: {=_xlfn._xlws.FILTER(SAP!$B$2,1)/COUNTA($G$2:$G$85)} -> 51.681905 | R18: =+SUM(P18:P21) -> 174.176 | S18: 932341308 | T18: 207 | U18: 2 | V18: Bolsa 5 | W18: A4BN | X18: 188
I19: A3BN | J19: =+SUMIFS('02'!C:C,'02'!J:J,D18&" - "&C18&" - "&H18,'02'!B:B,'2026-3'!$I19) -> 0 | K19: =+SUMIFS('02'!D:D,'02'!J:J,D18&" - "&C18&" - "&H18,'02'!B:B,'2026-3'!$I19) -> 0 | L19: =IF(K19-J19<=0,"0",K19-J19) -> 0 | N19: =IFERROR(+L19-M19,"") -> 0 | O19: =VALUE(+VLOOKUP(I19,'01'!C:K,9,FALSE)) -> 0.0301 | P19: =+N19*O19 -> 0 | V19: Bolsa 5 | W19: A3BN
I20: A4CL | J20: =+SUMIFS('02'!C:C,'02'!J:J,D18&" - "&C18&" - "&H18,'02'!B:B,'2026-3'!$I20) -> 21349 | K20: =+SUMIFS('02'!D:D,'02'!J:J,D18&" - "&C18&" - "&H18,'02'!B:B,'2026-3'!$I20) -> 25358 | L20: =IF(K20-J20<=0,"0",K20-J20) -> 4009 | M20: =SUMIFS(X:X,V:V,$H18,W:W,I20)/COUNTIF(H:H,$H18) -> 563 | N20: =IFERROR(+L20-M20,"") -> 3446 | O20: =VALUE(+VLOOKUP(I20,'01'!C:K,9,FALSE)) -> 0.0472 | P20: =+N20*O20 -> 162.6512 | V20: Bolsa 5 | W20: A4CL | X20: 563
I21: A3CL | J21: =+SUMIFS('02'!C:C,'02'!J:J,D18&" - "&C18&" - "&H18,'02'!B:B,'2026-3'!$I21) -> 0 | K21: =+SUMIFS('02'!D:D,'02'!J:J,D18&" - "&C18&" - "&H18,'02'!B:B,'2026-3'!$I21) -> 0 | L21: =IF(K21-J21<=0,"0",K21-J21) -> 0 | N21: =IFERROR(+L21-M21,"") -> 0 | O21: =VALUE(+VLOOKUP(I21,'01'!C:K,9,FALSE)) -> 0.0906 | P21: =+N21*O21 -> 0 | V21: Bolsa 5 | W21: A3CL
C22: WF-C5790 | D22: X3B7003659 | E22: 10.72.8.197 | F22: 3er Piso - Reservas | G22: 1 | H22: Bolsa 2 | I22: A4BN | J22: =+SUMIFS('02'!C:C,'02'!J:J,D22&" - "&C22&" - "&H22,'02'!B:B,'2026-3'!$I22) -> 15527 | K22: =+SUMIFS('02'!D:D,'02'!J:J,D22&" - "&C22&" - "&H22,'02'!B:B,'2026-3'!$I22) -> 15992 | L22: =IF(K22-J22<=0,"0",K22-J22) -> 465 | M22: =SUMIFS(X:X,V:V,H22,W:W,I22)/COUNTIF(H:H,H22) -> 188 | N22: =IFERROR(+L22-M22,"") -> 277 | O22: =VALUE(+VLOOKUP(I22,'01'!C:K,9,FALSE)) -> 0.0168 | P22: =+N22*O22 -> 4.6536 | Q22: {=_xlfn._xlws.FILTER(SAP!$B$2,1)/COUNTA($G$2:$G$85)} -> 51.681905 | R22: =+SUM(P22:P25) -> 17.0672 | S22: 943331308 | T22: 406 | U22: 2
I23: A3BN | J23: =+SUMIFS('02'!C:C,'02'!J:J,D22&" - "&C22&" - "&H22,'02'!B:B,'2026-3'!$I23) -> 0 | K23: =+SUMIFS('02'!D:D,'02'!J:J,D22&" - "&C22&" - "&H22,'02'!B:B,'2026-3'!$I23) -> 0 | L23: =IF(K23-J23<=0,"0",K23-J23) -> 0 | N23: =IFERROR(+L23-M23,"") -> 0 | O23: =VALUE(+VLOOKUP(I23,'01'!C:K,9,FALSE)) -> 0.0301 | P23: =+N23*O23 -> 0
I24: A4CL | J24: =+SUMIFS('02'!C:C,'02'!J:J,D22&" - "&C22&" - "&H22,'02'!B:B,'2026-3'!$I24) -> 14379 | K24: =+SUMIFS('02'!D:D,'02'!J:J,D22&" - "&C22&" - "&H22,'02'!B:B,'2026-3'!$I24) -> 15205 | L24: =IF(K24-J24<=0,"0",K24-J24) -> 826 | M24: =SUMIFS(X:X,V:V,$H22,W:W,I24)/COUNTIF(H:H,$H22) -> 563 | N24: =IFERROR(+L24-M24,"") -> 263 | O24: =VALUE(+VLOOKUP(I24,'01'!C:K,9,FALSE)) -> 0.0472 | P24: =+N24*O24 -> 12.4136
I25: A3CL | J25: =+SUMIFS('02'!C:C,'02'!J:J,D22&" - "&C22&" - "&H22,'02'!B:B,'2026-3'!$I25) -> 0 | K25: =+SUMIFS('02'!D:D,'02'!J:J,D22&" - "&C22&" - "&H22,'02'!B:B,'2026-3'!$I25) -> 0 | L25: =IF(K25-J25<=0,"0",K25-J25) -> 0 | N25: =IFERROR(+L25-M25,"") -> 0 | O25: =VALUE(+VLOOKUP(I25,'01'!C:K,9,FALSE)) -> 0.0906 | P25: =+N25*O25 -> 0
C26: WF-C5790 | D26: X3B7003660 | E26: 10.72.8.204 | F26: 1er Piso - Room Service | G26: 1 | H26: Bolsa 2 | I26: A4BN | J26: =+SUMIFS('02'!C:C,'02'!J:J,D26&" - "&C26&" - "&H26,'02'!B:B,'2026-3'!$I26) -> 83188 | K26: =+SUMIFS('02'!D:D,'02'!J:J,D26&" - "&C26&" - "&H26,'02'!B:B,'2026-3'!$I26) -> 83943 | L26: =IF(K26-J26<=0,"0",K26-J26) -> 755 | M26: =SUMIFS(X:X,V:V,H26,W:W,I26)/COUNTIF(H:H,H26) -> 188 | N26: =IFERROR(+L26-M26,"") -> 567 | O26: =VALUE(+VLOOKUP(I26,'01'!C:K,9,FALSE)) -> 0.0168 | P26: =+N26*O26 -> 9.5256 | Q26: {=_xlfn._xlws.FILTER(SAP!$B$2,1)/COUNTA($G$2:$G$85)} -> 51.681905 | R26: =+SUM(P26:P29) -> 81.9776 | S26: 932341308 | T26: 206 | U26: 2
I27: A3BN | J27: =+SUMIFS('02'!C:C,'02'!J:J,D26&" - "&C26&" - "&H26,'02'!B:B,'2026-3'!$I27) -> 0 | K27: =+SUMIFS('02'!D:D,'02'!J:J,D26&" - "&C26&" - "&H26,'02'!B:B,'2026-3'!$I27) -> 0 | L27: =IF(K27-J27<=0,"0",K27-J27) -> 0 | N27: =IFERROR(+L27-M27,"") -> 0 | O27: =VALUE(+VLOOKUP(I27,'01'!C:K,9,FALSE)) -> 0.0301 | P27: =+N27*O27 -> 0 | W27: X3B7003661 - WF-C5790
I28: A4CL | J28: =+SUMIFS('02'!C:C,'02'!J:J,D26&" - "&C26&" - "&H26,'02'!B:B,'2026-3'!$I28) -> 18110 | K28: =+SUMIFS('02'!D:D,'02'!J:J,D26&" - "&C26&" - "&H26,'02'!B:B,'2026-3'!$I28) -> 20208 | L28: =IF(K28-J28<=0,"0",K28-J28) -> 2098 | M28: =SUMIFS(X:X,V:V,$H26,W:W,I28)/COUNTIF(H:H,$H26) -> 563 | N28: =IFERROR(+L28-M28,"") -> 1535 | O28: =VALUE(+VLOOKUP(I28,'01'!C:K,9,FALSE)) -> 0.0472 | P28: =+N28*O28 -> 72.452 | W28: =D30&" - "&C30&" - "&H30 -> X3B7003661 - WF-C5790 -
I29: A3CL | J29: =+SUMIFS('02'!C:C,'02'!J:J,D26&" - "&C26&" - "&H26,'02'!B:B,'2026-3'!$I29) -> 0 | K29: =+SUMIFS('02'!D:D,'02'!J:J,D26&" - "&C26&" - "&H26,'02'!B:B,'2026-3'!$I29) -> 0 | L29: =IF(K29-J29<=0,"0",K29-J29) -> 0 | N29: =IFERROR(+L29-M29,"") -> 0 | O29: =VALUE(+VLOOKUP(I29,'01'!C:K,9,FALSE)) -> 0.0906 | P29: =+N29*O29 -> 0
C30: WF-C5790 | D30: X3B7003661 | E30: 10.72.8.132 | F30: 1er Sotano - Steward - Limpieza | G30: 1 | I30: A4BN | J30: =+SUMIFS('02'!C:C,'02'!J:J,D30&" - "&C30,'02'!B:B,'2026-3'!$I30) -> 13075 | K30: =+SUMIFS('02'!D:D,'02'!J:J,D30&" - "&C30,'02'!B:B,'2026-3'!$I30) -> 20147 | L30: =IF(K30-J30<=0,"0",K30-J30) -> 7072 | M30: =IFERROR(+SUMIFS(X:X,V:V,H30,W:W,I30)/COUNTIF(H:H,H30),"") | N30: =IFERROR(+L30-M30,"") | O30: =VALUE(+VLOOKUP(I30,'01'!C:K,9,FALSE)) -> 0.0168 | P30: =+O30*L30 -> 118.8096 | Q30: {=_xlfn._xlws.FILTER(SAP!$B$2,1)/COUNTA($G$2:$G$85)} -> 51.681905 | R30: =SUM(P30:P33) -> 437.3624 | S30: 932341308 | T30: 200 | W30: =+EXACT(W28,W27) -> FALSE
I31: A3BN | J31: =+SUMIFS('02'!C:C,'02'!J:J,D30&" - "&C30,'02'!B:B,'2026-3'!$I31) -> 0 | K31: =+SUMIFS('02'!D:D,'02'!J:J,D30&" - "&C30,'02'!B:B,'2026-3'!$I31) -> 0 | L31: =IF(K31-J31<=0,"0",K31-J31) -> 0 | N31: =IFERROR(+L31-M31,"") -> 0 | O31: =VALUE(+VLOOKUP(I31,'01'!C:K,9,FALSE)) -> 0.0301 | P31: =+O31*L31 -> 0
I32: A4CL | J32: =+SUMIFS('02'!C:C,'02'!J:J,D30&" - "&C30,'02'!B:B,'2026-3'!$I32) -> 6457 | K32: =+SUMIFS('02'!D:D,'02'!J:J,D30&" - "&C30,'02'!B:B,'2026-3'!$I32) -> 13206 | L32: =IF(K32-J32<=0,"0",K32-J32) -> 6749 | M32: =IFERROR(+SUMIFS(X:X,V:V,$H30,W:W,I32)/COUNTIF(H:H,$H30),"") | N32: =IFERROR(+L32-M32,"") | O32: =VALUE(+VLOOKUP(I32,'01'!C:K,9,FALSE)) -> 0.0472 | P32: =+O32*L32 -> 318.5528
I33: A3CL | J33: =+SUMIFS('02'!C:C,'02'!J:J,D30&" - "&C30,'02'!B:B,'2026-3'!$I33) -> 0 | K33: =+SUMIFS('02'!D:D,'02'!J:J,D30&" - "&C30,'02'!B:B,'2026-3'!$I33) -> 0 | L33: =IF(K33-J33<=0,"0",K33-J33) -> 0 | N33: =IFERROR(+L33-M33,"") -> 0 | O33: =VALUE(+VLOOKUP(I33,'01'!C:K,9,FALSE)) -> 0.0906 | P33: =+O33*L33 -> 0
C34: WF-C5790 | D34: X3B7003671 | E34: 10.72.8.208 | F34: 1er Piso - Caja Lobby Bar | G34: 1 | H34: Bolsa 2 | I34: A4BN | J34: =+SUMIFS('02'!C:C,'02'!J:J,D34&" - "&C34&" - "&H34,'02'!B:B,'2026-3'!$I34) -> 9497 | K34: =+SUMIFS('02'!D:D,'02'!J:J,D34&" - "&C34&" - "&H34,'02'!B:B,'2026-3'!$I34) -> 9830 | L34: =IF(K34-J34<=0,"0",K34-J34) -> 333 | M34: =SUMIFS(X:X,V:V,H34,W:W,I34)/COUNTIF(H:H,H34) -> 188 | N34: =IFERROR(+L34-M34,"") -> 145 | O34: =VALUE(+VLOOKUP(I34,'01'!C:K,9,FALSE)) -> 0.0168 | P34: =+N34*O34 -> 2.436 | Q34: {=_xlfn._xlws.FILTER(SAP!$B$2,1)/COUNTA($G$2:$G$85)} -> 51.681905 | R34: =+SUM(P34:P37) -> 1.8696 | S34: 932341308 | T34: 204
I35: A3BN | J35: =+SUMIFS('02'!C:C,'02'!J:J,D34&" - "&C34&" - "&H34,'02'!B:B,'2026-3'!$I35) -> 0 | K35: =+SUMIFS('02'!D:D,'02'!J:J,D34&" - "&C34&" - "&H34,'02'!B:B,'2026-3'!$I35) -> 0 | L35: =IF(K35-J35<=0,"0",K35-J35) -> 0 | N35: =IFERROR(+L35-M35,"") -> 0 | O35: =VALUE(+VLOOKUP(I35,'01'!C:K,9,FALSE)) -> 0.0301 | P35: =+N35*O35 -> 0
I36: A4CL | J36: =+SUMIFS('02'!C:C,'02'!J:J,D34&" - "&C34&" - "&H34,'02'!B:B,'2026-3'!$I36) -> 4511 | K36: =+SUMIFS('02'!D:D,'02'!J:J,D34&" - "&C34&" - "&H34,'02'!B:B,'2026-3'!$I36) -> 5062 | L36: =IF(K36-J36<=0,"0",K36-J36) -> 551 | M36: =SUMIFS(X:X,V:V,$H34,W:W,I36)/COUNTIF(H:H,$H34) -> 563 | N36: =IFERROR(+L36-M36,"") -> -12 | O36: =VALUE(+VLOOKUP(I36,'01'!C:K,9,FALSE)) -> 0.0472 | P36: =+N36*O36 -> -0.5664
I37: A3CL | J37: =+SUMIFS('02'!C:C,'02'!J:J,D34&" - "&C34&" - "&H34,'02'!B:B,'2026-3'!$I37) -> 0 | K37: =+SUMIFS('02'!D:D,'02'!J:J,D34&" - "&C34&" - "&H34,'02'!B:B,'2026-3'!$I37) -> 0 | L37: =IF(K37-J37<=0,"0",K37-J37) -> 0 | N37: =IFERROR(+L37-M37,"") -> 0 | O37: =VALUE(+VLOOKUP(I37,'01'!C:K,9,FALSE)) -> 0.0906 | P37: =+N37*O37 -> 0
C38: WF-C5790 | D38: X3B7003703 | E38: 10.9.10.153 | F38: 1er Piso Gym | G38: 1 | H38: Bolsa 2 | I38: A4BN | J38: =+SUMIFS('02'!C:C,'02'!J:J,D38&" - "&C38&" - "&H38,'02'!B:B,'2026-3'!$I38) -> 85135 | K38: =+SUMIFS('02'!D:D,'02'!J:J,D38&" - "&C38&" - "&H38,'02'!B:B,'2026-3'!$I38) -> 88863 | L38: =IF(K38-J38<=0,"0",K38-J38) -> 3728 | M38: =1504/COUNTIF(H:H,"Bolsa 2") -> 188 | N38: =IFERROR(+L38-M38,"") -> 3540 | O38: =VALUE(+VLOOKUP(I38,'01'!C:K,9,FALSE)) -> 0.0168 | P38: =+N38*O38 -> 59.472 | Q38: {=_xlfn._xlws.FILTER(SAP!$B$2,1)/COUNTA($G$2:$G$85)} -> 51.681905 | R38: =+SUM(P38:P41) -> 55.46 | S38: 933441108 | T38: 304
I39: A3BN | J39: =+SUMIFS('02'!C:C,'02'!J:J,D38&" - "&C38&" - "&H38,'02'!B:B,'2026-3'!$I39) -> 0 | K39: =+SUMIFS('02'!D:D,'02'!J:J,D38&" - "&C38&" - "&H38,'02'!B:B,'2026-3'!$I39) -> 0 | L39: =IF(K39-J39<=0,"0",K39-J39) -> 0 | N39: =IFERROR(+L39-M39,"") -> 0 | O39: =VALUE(+VLOOKUP(I39,'01'!C:K,9,FALSE)) -> 0.0301 | P39: =+N39*O39 -> 0
I40: A4CL | J40: =+SUMIFS('02'!C:C,'02'!J:J,D38&" - "&C38&" - "&H38,'02'!B:B,'2026-3'!$I40) -> 9094 | K40: =+SUMIFS('02'!D:D,'02'!J:J,D38&" - "&C38&" - "&H38,'02'!B:B,'2026-3'!$I40) -> 9572 | L40: =IF(K40-J40<=0,"0",K40-J40) -> 478 | M40: =SUMIFS(X:X,V:V,$H38,W:W,I40)/COUNTIF(H:H,$H38) -> 563 | N40: =IFERROR(+L40-M40,"") -> -85 | O40: =VALUE(+VLOOKUP(I40,'01'!C:K,9,FALSE)) -> 0.0472 | P40: =+N40*O40 -> -4.012
...

Sheet 2026
B2: REPORTE DE COPIAS - REPRODATA 2026-2026
D5: 44562 | I5: 44593 | M5: 44621 | Q5: 44652 | U5: 44682 | Y5: 44713 | AC5: 44743
B6: SERIE DE EQUIPO | C6: UBICACION / AREA | D6: Tipo | E6: Bolsa | F6: Cantidad | G6: Precio $ | H6: Total | I6: Tipo | J6: Cantidad | K6: Precio $ | L6: Total | M6: Tipo | N6: Cantidad | O6: Precio $ | P6: Total | Q6: Tipo | R6: Cantidad | S6: Precio $ | T6: Total | U6: Tipo | V6: Cantidad | W6: Precio $ | X6: Total | Y6: Tipo | Z6: Cantidad | AA6: Precio $ | AB6: Total | AC6: Tipo | AD6: Cantidad | AE6: Precio $ | AF6: Total
B7: X3B7003661 - WF-C5790 | C7: Contabilidad | D7: A4BN | G7: 0.0111 | H7: =+F7*G7 -> 0 | I7: B/N | J7: 1625 | K7: 0.0111 | L7: =+J7*K7 -> 18.0375 | M7: B/N | N7: 2826 | O7: 0.0111 | P7: =+N7*O7 -> 31.3686 | Q7: B/N | R7: 1912 | S7: 0.0111 | T7: =+R7*S7 -> 21.2232 | U7: B/N | V7: 2371 | W7: 0.0111 | X7: =+V7*W7 -> 26.3181 | Y7: B/N | Z7: 1644 | AA7: 0.0111 | AB7: =+Z7*AA7 -> 18.2484 | AC7: B/N | AD7: 23230 | AE7: 0.0111 | AF7: =+AD7*AE7 -> 257.853
D8: A3BN
D9: A4CL
D10: A3CL | G10: 0.0501 | H10: =+F10*G10 -> 0 | I10: Colores | K10: 0.0501 | L10: =+J10*K10 -> 0 | M10: Colores | O10: 0.0501 | P10: =+N10*O10 -> 0 | Q10: Colores | S10: 0.0501 | T10: =+R10*S10 -> 0 | U10: Colores | W10: 0.0501 | X10: =+V10*W10 -> 0 | Y10: Colores | AA10: 0.0501 | AB10: =+Z10*AA10 -> 0 | AC10: Colores | AE10: 0.0501 | AF10: =+AD10*AE10 -> 0
B11: X3B7003581 | C11: C&M Oficina | D11: B/N | F11: 325 | G11: 0.0198 | H11: =+F11*G11 -> 6.435 | I11: B/N | J11: 686 | K11: 0.0198 | L11: =+J11*K11 -> 13.5828 | M11: B/N | N11: 347 | O11: 0.0198 | P11: =+N11*O11 -> 6.8706 | Q11: B/N | R11: 248 | S11: 0.0198 | T11: =+R11*S11 -> 4.9104 | U11: B/N | V11: 600 | W11: 0.0198 | X11: =+V11*W11 -> 11.88 | Y11: B/N | Z11: 1197 | AA11: 0.0198 | AB11: =+Z11*AA11 -> 23.7006 | AC11: B/N | AD11: 753 | AE11: 0.0198 | AF11: =+AD11*AE11 -> 14.9094
B12: X3B7003581 | C12: C&M Oficina | D12: Colores | F12: 2 | G12: 0.0501 | H12: =+F12*G12 -> 0.1002 | I12: Colores | K12: 0.0501 | L12: =+J12*K12 -> 0 | M12: Colores | O12: 0.0501 | P12: =+N12*O12 -> 0 | Q12: Colores | S12: 0.0501 | T12: =+R12*S12 -> 0 | U12: Colores | V12: 1 | W12: 0.0501 | X12: =+V12*W12 -> 0.0501 | Y12: Colores | AA12: 0.0501 | AB12: =+Z12*AA12 -> 0 | AC12: Colores | AE12: 0.0501 | AF12: =+AD12*AE12 -> 0
B13: X3B7003609 | C13: Talento y Cultura | D13: B/N | F13: 2436 | G13: 0.0198 | H13: =+F13*G13 -> 48.2328 | I13: B/N | J13: 1994 | K13: 0.0198 | L13: =+J13*K13 -> 39.4812 | M13: B/N | N13: 2678 | O13: 0.0198 | P13: =+N13*O13 -> 53.0244 | Q13: B/N | R13: 2164 | S13: 0.0198 | T13: =+R13*S13 -> 42.8472 | U13: B/N | V13: 1972 | W13: 0.0198 | X13: =+V13*W13 -> 39.0456 | Y13: B/N | Z13: 904 | AA13: 0.0198 | AB13: =+Z13*AA13 -> 17.8992 | AC13: B/N | AD13: 2482 | AE13: 0.0198 | AF13: =+AD13*AE13 -> 49.1436
B14: X3B7003609 | C14: Talento y Cultura | D14: Colores | F14: 187 | G14: 0.0501 | H14: =+F14*G14 -> 9.3687 | I14: Colores | J14: 82 | K14: 0.0501 | L14: =+J14*K14 -> 4.1082 | M14: Colores | N14: 4215 | O14: 0.0501 | P14: =+N14*O14 -> 211.1715 | Q14: Colores | R14: 141 | S14: 0.0501 | T14: =+R14*S14 -> 7.0641 | U14: Colores | V14: 34 | W14: 0.0501 | X14: =+V14*W14 -> 1.7034 | Y14: Colores | Z14: 266 | AA14: 0.0501 | AB14: =+Z14*AA14 -> 13.3266 | AC14: Colores | AD14: 207 | AE14: 0.0501 | AF14: =+AD14*AE14 -> 10.3707
A15: No se usa | B15: X3B7003615 | C15: Disponible | D15: B/N | G15: 0.0198 | H15: =+F15*G15 -> 0 | I15: B/N | K15: 0.0198 | L15: =+J15*K15 -> 0 | M15: B/N | O15: 0.0198 | P15: =+N15*O15 -> 0 | Q15: B/N | S15: 0.0198 | T15: =+R15*S15 -> 0 | U15: B/N | W15: 0.0198 | X15: =+V15*W15 -> 0 | Y15: B/N | Z15: 12 | AA15: 0.0198 | AB15: =+Z15*AA15 -> 0.2376 | AC15: B/N | AD15: 1819 | AE15: 0.0198 | AF15: =+AD15*AE15 -> 36.0162
A16: No se usa | B16: X3B7003615 | C16: Disponible | D16: Colores | G16: 0.0501 | H16: =+F16*G16 -> 0 | I16: Colores | K16: 0.0501 | L16: =+J16*K16 -> 0 | M16: Colores | O16: 0.0501 | P16: =+N16*O16 -> 0 | Q16: Colores | S16: 0.0501 | T16: =+R16*S16 -> 0 | U16: Colores | W16: 0.0501 | X16: =+V16*W16 -> 0 | Y16: Colores | Z16: 10 | AA16: 0.0501 | AB16: =+Z16*AA16 -> 0.501 | AC16: Colores | AD16: 1208 | AE16: 0.0501 | AF16: =+AD16*AE16 -> 60.5208
B17: X3B7003656 | C17: Concierge | D17: B/N | F17: 127 | G17: 0.0198 | H17: =+F17*G17 -> 2.5146 | I17: B/N | J17: 660 | K17: 0.0198 | L17: =+J17*K17 -> 13.068 | M17: B/N | N17: 533 | O17: 0.0198 | P17: =+N17*O17 -> 10.5534 | Q17: B/N | R17: 541 | S17: 0.0198 | T17: =+R17*S17 -> 10.7118 | U17: B/N | V17: 607 | W17: 0.0198 | X17: =+V17*W17 -> 12.0186 | Y17: B/N | Z17: 586 | AA17: 0.0198 | AB17: =+Z17*AA17 -> 11.6028 | AC17: B/N | AD17: 521 | AE17: 0.0198 | AF17: =+AD17*AE17 -> 10.3158
B18: X3B7003656 | C18: Concierge | D18: Colores | F18: 24 | G18: 0.0501 | H18: =+F18*G18 -> 1.2024 | I18: Colores | J18: 86 | K18: 0.0501 | L18: =+J18*K18 -> 4.3086 | M18: Colores | N18: 23 | O18: 0.0501 | P18: =+N18*O18 -> 1.1523 | Q18: Colores | R18: 63 | S18: 0.0501 | T18: =+R18*S18 -> 3.1563 | U18: Colores | V18: 204 | W18: 0.0501 | X18: =+V18*W18 -> 10.2204 | Y18: Colores | Z18: 132 | AA18: 0.0501 | AB18: =+Z18*AA18 -> 6.6132 | AC18: Colores | AD18: 50 | AE18: 0.0501 | AF18: =+AD18*AE18 -> 2.505
B19: X3B7003659 | C19: Asistente Gerencia General | D19: B/N | G19: 0.0198 | H19: =+F19*G19 -> 0 | I19: B/N | J19: 384 | K19: 0.0198 | L19: =+J19*K19 -> 7.6032 | M19: B/N | N19: 70 | O19: 0.0198 | P19: =+N19*O19 -> 1.386 | Q19: B/N | R19: 142 | S19: 0.0198 | T19: =+R19*S19 -> 2.8116 | U19: B/N | V19: 143 | W19: 0.0198 | X19: =+V19*W19 -> 2.8314 | Y19: B/N | Z19: 101 | AA19: 0.0198 | AB19: =+Z19*AA19 -> 1.9998 | AC19: B/N | AD19: 154 | AE19: 0.0198 | AF19: =+AD19*AE19 -> 3.0492
B20: X3B7003659 | C20: Asistente Gerencia General | D20: Colores | F20: 40 | G20: 0.0501 | H20: =+F20*G20 -> 2.004 | I20: Colores | J20: 394 | K20: 0.0501 | L20: =+J20*K20 -> 19.7394 | M20: Colores | N20: 281 | O20: 0.0501 | P20: =+N20*O20 -> 14.0781 | Q20: Colores | R20: 195 | S20: 0.0501 | T20: =+R20*S20 -> 9.7695 | U20: Colores | V20: 123 | W20: 0.0501 | X20: =+V20*W20 -> 6.1623 | Y20: Colores | Z20: 84 | AA20: 0.0501 | AB20: =+Z20*AA20 -> 4.2084 | AC20: Colores | AD20: 214 | AE20: 0.0501 | AF20: =+AD20*AE20 -> 10.7214
B21: X3B7003660 | C21: Room Service | D21: B/N | F21: 2077 | G21: 0.0198 | H21: =+F21*G21 -> 41.1246 | I21: B/N | J21: 1547 | K21: 0.0198 | L21: =+J21*K21 -> 30.6306 | M21: B/N | N21: 1326 | O21: 0.0198 | P21: =+N21*O21 -> 26.2548 | Q21: B/N | R21: 789 | S21: 0.0198 | T21: =+R21*S21 -> 15.6222 | U21: B/N | V21: 1131 | W21: 0.0198 | X21: =+V21*W21 -> 22.3938 | Y21: B/N | Z21: 800 | AA21: 0.0198 | AB21: =+Z21*AA21 -> 15.84 | AC21: B/N | AD21: 810 | AE21: 0.0198 | AF21: =+AD21*AE21 -> 16.038
B22: X3B7003660 | C22: Room Service | D22: Colores | G22: 0.0501 | H22: =+F22*G22 -> 0 | I22: Colores | K22: 0.0501 | L22: =+J22*K22 -> 0 | M22: Colores | O22: 0.0501 | P22: =+N22*O22 -> 0 | Q22: Colores | S22: 0.0501 | T22: =+R22*S22 -> 0 | U22: Colores | V22: 2 | W22: 0.0501 | X22: =+V22*W22 -> 0.1002 | Y22: Colores | AA22: 0.0501 | AB22: =+Z22*AA22 -> 0 | AC22: Colores | AE22: 0.0501 | AF22: =+AD22*AE22 -> 0
A23: No se usa | B23: X3B7003661 | C23: Disponible | D23: B/N | G23: 0.0198 | H23: =+F23*G23 -> 0 | I23: B/N | K23: 0.0198 | L23: =+J23*K23 -> 0 | M23: B/N | O23: 0.0198 | P23: =+N23*O23 -> 0 | Q23: B/N | S23: 0.0198 | T23: =+R23*S23 -> 0 | U23: B/N | W23: 0.0198 | X23: =+V23*W23 -> 0 | Y23: B/N | AA23: 0.0198 | AB23: =+Z23*AA23 -> 0 | AC23: B/N | AE23: 0.0198 | AF23: =+AD23*AE23 -> 0
A24: No se usa | B24: X3B7003661 | C24: Disponible | D24: Colores | G24: 0.0501 | H24: =+F24*G24 -> 0 | I24: Colores | K24: 0.0501 | L24: =+J24*K24 -> 0 | M24: Colores | O24: 0.0501 | P24: =+N24*O24 -> 0 | Q24: Colores | S24: 0.0501 | T24: =+R24*S24 -> 0 | U24: Colores | W24: 0.0501 | X24: =+V24*W24 -> 0 | Y24: Colores | AA24: 0.0501 | AB24: =+Z24*AA24 -> 0 | AC24: Colores | AE24: 0.0501 | AF24: =+AD24*AE24 -> 0
B25: X3B7003671 | C25: Compras | D25: B/N | F25: 42 | G25: 0.0198 | H25: =+F25*G25 -> 0.8316 | I25: B/N | J25: 80 | K25: 0.0198 | L25: =+J25*K25 -> 1.584 | M25: B/N | N25: 127 | O25: 0.0198 | P25: =+N25*O25 -> 2.5146 | Q25: B/N | R25: 68 | S25: 0.0198 | T25: =+R25*S25 -> 1.3464 | U25: B/N | V25: 105 | W25: 0.0198 | X25: =+V25*W25 -> 2.079 | Y25: B/N | Z25: 91 | AA25: 0.0198 | AB25: =+Z25*AA25 -> 1.8018 | AC25: B/N | AD25: 123 | AE25: 0.0198 | AF25: =+AD25*AE25 -> 2.4354
B26: X3B7003671 | C26: Compras | D26: Colores | F26: 21 | G26: 0.0501 | H26: =+F26*G26 -> 1.0521 | I26: Colores | J26: 38 | K26: 0.0501 | L26: =+J26*K26 -> 1.9038 | M26: Colores | N26: 60 | O26: 0.0501 | P26: =+N26*O26 -> 3.006 | Q26: Colores | R26: 31 | S26: 0.0501 | T26: =+R26*S26 -> 1.5531 | U26: Colores | V26: 34 | W26: 0.0501 | X26: =+V26*W26 -> 1.7034 | Y26: Colores | Z26: 18 | AA26: 0.0501 | AB26: =+Z26*AA26 -> 0.9018 | AC26: Colores | AD26: 35 | AE26: 0.0501 | AF26: =+AD26*AE26 -> 1.7535
B27: X3B7003690 | C27: Cuadres | D27: B/N | G27: 0.0198 | H27: =+F27*G27 -> 0 | I27: B/N | K27: 0.0198 | L27: =+J27*K27 -> 0 | M27: B/N | N27: 13 | O27: 0.0198 | P27: =+N27*O27 -> 0.2574 | Q27: B/N | R27: 372 | S27: 0.0198 | T27: =+R27*S27 -> 7.3656 | U27: B/N | V27: 372 | W27: 0.0198 | X27: =+V27*W27 -> 7.3656 | Y27: B/N | Z27: 225 | AA27: 0.0198 | AB27: =+Z27*AA27 -> 4.455 | AC27: B/N | AD27: 323 | AE27: 0.0198 | AF27: =+AD27*AE27 -> 6.3954
B28: X3B7003690 | C28: Cuadres | D28: Colores | G28: 0.0501 | H28: =+F28*G28 -> 0 | I28: Colores | J28: 165 | K28: 0.0501 | L28: =+J28*K28 -> 8.2665 | M28: Colores | N28: 232 | O28: 0.0501 | P28: =+N28*O28 -> 11.6232 | Q28: Colores | S28: 0.0501 | T28: =+R28*S28 -> 0 | U28: Colores | V28: 37 | W28: 0.0501 | X28: =+V28*W28 -> 1.8537 | Y28: Colores | Z28: 7 | AA28: 0.0501 | AB28: =+Z28*AA28 -> 0.3507 | AC28: Colores | AD28: 25 | AE28: 0.0501 | AF28: =+AD28*AE28 -> 1.2525
B29: X3B7003703 | C29: GYM | D29: B/N | F29: 1944 | G29: 0.0198 | H29: =+F29*G29 -> 38.4912 | I29: B/N | J29: 926 | K29: 0.0198 | L29: =+J29*K29 -> 18.3348 | M29: B/N | N29: 1253 | O29: 0.0198 | P29: =+N29*O29 -> 24.8094 | Q29: B/N | R29: 1527 | S29: 0.0198 | T29: =+R29*S29 -> 30.2346 | U29: B/N | V29: 1166 | W29: 0.0198 | X29: =+V29*W29 -> 23.0868 | Y29: B/N | Z29: 1418 | AA29: 0.0198 | AB29: =+Z29*AA29 -> 28.0764 | AC29: B/N | AD29: 2093 | AE29: 0.0198 | AF29: =+AD29*AE29 -> 41.4414
B30: X3B7003703 | C30: GYM | D30: Colores | F30: 784 | G30: 0.0501 | H30: =+F30*G30 -> 39.2784 | I30: Colores | J30: 27 | K30: 0.0501 | L30: =+J30*K30 -> 1.3527 | M30: Colores | N30: 31 | O30: 0.0501 | P30: =+N30*O30 -> 1.5531 | Q30: Colores | R30: 134 | S30: 0.0501 | T30: =+R30*S30 -> 6.7134 | U30: Colores | V30: 81 | W30: 0.0501 | X30: =+V30*W30 -> 4.0581 | Y30: Colores | Z30: 56 | AA30: 0.0501 | AB30: =+Z30*AA30 -> 2.8056 | AC30: Colores | AD30: 63 | AE30: 0.0501 | AF30: =+AD30*AE30 -> 3.1563
B31: X3B7003711 | C31: Oficina de Recepción | D31: B/N | F31: 1186 | G31: 0.0198 | H31: =+F31*G31 -> 23.4828 | I31: B/N | J31: 1165 | K31: 0.0198 | L31: =+J31*K31 -> 23.067 | M31: B/N | N31: 797 | O31: 0.0198 | P31: =+N31*O31 -> 15.7806 | Q31: B/N | R31: 1074 | S31: 0.0198 | T31: =+R31*S31 -> 21.2652 | U31: B/N | V31: 1074 | W31: 0.0198 | X31: =+V31*W31 -> 21.2652 | Y31: B/N | Z31: 1257 | AA31: 0.0198 | AB31: =+Z31*AA31 -> 24.8886 | AC31: B/N | AD31: 1167 | AE31: 0.0198 | AF31: =+AD31*AE31 -> 23.1066
B32: X3B7003711 | C32: Oficina de Recepción | D32: Colores | F32: 193 | G32: 0.0501 | H32: =+F32*G32 -> 9.6693 | I32: Colores | J32: 335 | K32: 0.0501 | L32: =+J32*K32 -> 16.7835 | M32: Colores | N32: 312 | O32: 0.0501 | P32: =+N32*O32 -> 15.6312 | Q32: Colores | R32: 211 | S32: 0.0501 | T32: =+R32*S32 -> 10.5711 | U32: Colores | V32: 414 | W32: 0.0501 | X32: =+V32*W32 -> 20.7414 | Y32: Colores | Z32: 318 | AA32: 0.0501 | AB32: =+Z32*AA32 -> 15.9318 | AC32: Colores | AD32: 516 | AE32: 0.0501 | AF32: =+AD32*AE32 -> 25.8516
B33: X3B7003712 | C33: Bodegas | D33: B/N | F33: 262 | G33: 0.0198 | H33: =+F33*G33 -> 5.1876 | I33: B/N | J33: 480 | K33: 0.0198 | L33: =+J33*K33 -> 9.504 | M33: B/N | N33: 554 | O33: 0.0198 | P33: =+N33*O33 -> 10.9692 | Q33: B/N | R33: 447 | S33: 0.0198 | T33: =+R33*S33 -> 8.8506 | U33: B/N | V33: 480 | W33: 0.0198 | X33: =+V33*W33 -> 9.504 | Y33: B/N | Z33: 411 | AA33: 0.0198 | AB33: =+Z33*AA33 -> 8.1378 | AC33: B/N | AD33: 490 | AE33: 0.0198 | AF33: =+AD33*AE33 -> 9.702
B34: X3B7003712 | C34: Bodegas | D34: Colores | F34: 19 | G34: 0.0501 | H34: =+F34*G34 -> 0.9519 | I34: Colores | J34: 38 | K34: 0.0501 | L34: =+J34*K34 -> 1.9038 | M34: Colores | O34: 0.0501 | P34: =+N34*O34 -> 0 | Q34: Colores | S34: 0.0501 | T34: =+R34*S34 -> 0 | U34: Colores | V34: 3 | W34: 0.0501 | X34: =+V34*W34 -> 0.1503 | Y34: Colores | AA34: 0.0501 | AB34: =+Z34*AA34 -> 0 | AC34: Colores | AE34: 0.0501 | AF34: =+AD34*AE34 -> 0
B35: X3B7003716 | C35: Limpieza | D35: B/N | F35: 213 | G35: 0.0198 | H35: =+F35*G35 -> 4.2174 | I35: B/N | J35: 419 | K35: 0.0198 | L35: =+J35*K35 -> 8.2962 | M35: B/N | N35: 183 | O35: 0.0198 | P35: =+N35*O35 -> 3.6234 | Q35: B/N | R35: 80 | S35: 0.0198 | T35: =+R35*S35 -> 1.584 | U35: B/N | V35: 100 | W35: 0.0198 | X35: =+V35*W35 -> 1.98 | Y35: B/N | Z35: 157 | AA35: 0.0198 | AB35: =+Z35*AA35 -> 3.1086 | AC35: B/N | AD35: 146 | AE35: 0.0198 | AF35: =+AD35*AE35 -> 2.8908
B36: X3B7003716 | C36: Limpieza | D36: Colores | G36: 0.0501 | H36: =+F36*G36 -> 0 | I36: Colores | K36: 0.0501 | L36: =+J36*K36 -> 0 | M36: Colores | O36: 0.0501 | P36: =+N36*O36 -> 0 | Q36: Colores | S36: 0.0501 | T36: =+R36*S36 -> 0 | U36: Colores | V36: 2 | W36: 0.0501 | X36: =+V36*W36 -> 0.1002 | Y36: Colores | AA36: 0.0501 | AB36: =+Z36*AA36 -> 0 | AC36: Colores | AE36: 0.0501 | AF36: =+AD36*AE36 -> 0
B37: X3B7003751 | C37: Housekeeping | D37: B/N | F37: 2300 | G37: 0.0198 | H37: =+F37*G37 -> 45.54 | I37: B/N | J37: 2149 | K37: 0.0198 | L37: =+J37*K37 -> 42.5502 | M37: B/N | N37: 2167 | O37: 0.0198 | P37: =+N37*O37 -> 42.9066 | Q37: B/N | R37: 2270 | S37: 0.0198 | T37: =+R37*S37 -> 44.946 | U37: B/N | V37: 2070 | W37: 0.0198 | X37: =+V37*W37 -> 40.986 | Y37: B/N | Z37: 1291 | AA37: 0.0198 | AB37: =+Z37*AA37 -> 25.5618 | AC37: B/N | AD37: 3167 | AE37: 0.0198 | AF37: =+AD37*AE37 -> 62.7066
B38: X3B7003751 | C38: Housekeeping | D38: Colores | G38: 0.0501 | H38: =+F38*G38 -> 0 | I38: Colores | K38: 0.0501 | L38: =+J38*K38 -> 0 | M38: Colores | O38: 0.0501 | P38: =+N38*O38 -> 0 | Q38: Colores | S38: 0.0501 | T38: =+R38*S38 -> 0 | U38: Colores | W38: 0.0501 | X38: =+V38*W38 -> 0 | Y38: Colores | AA38: 0.0501 | AB38: =+Z38*AA38 -> 0 | AC38: Colores | AE38: 0.0501 | AF38: =+AD38*AE38 -> 0
